Workbook
Name SegmentaciónDeDatos_DIAS_RETRASO: #N/A
Name SegmentaciónDeDatos_DIAS_RETRASO1: #N/A
Name SegmentaciónDeDatos_DIAS_RETRASO2: #N/A
Name SegmentaciónDeDatos_DIAS_RETRASO3: #N/A
Name SegmentaciónDeDatos_DIAS_RETRASO4: #N/A
Name SegmentaciónDeDatos_DIAS_SIN_MOVIMIENTO: #N/A
Name SegmentaciónDeDatos_DIAS_SIN_MOVIMIENTO1: #N/A
Name SegmentaciónDeDatos_DIAS_SIN_MOVIMIENTO11: #N/A
Name SegmentaciónDeDatos_DIAS_SIN_MOVIMIENTO111: #N/A
Name SegmentaciónDeDatos_DIAS_SIN_MOVIMIENTO1111: #N/A
Name SegmentaciónDeDatos_ELÉCTRICO: #N/A
Name SegmentaciónDeDatos_SANITARIO: #N/A
Name SegmentaciónDeDatos_TIPO: #N/A
Name SegmentaciónDeDatos_TIPO1: #N/A
Name SegmentaciónDeDatos_TIPO11: #N/A
Name SegmentaciónDeDatos_TIPO111: #N/A
Name SegmentaciónDeDatos_TIPO1111: #N/A
Name SegmentaciónDeDatos_TORRE: #N/A
Name SegmentaciónDeDatos_TORRE1: #N/A
Name SegmentaciónDeDatos_TORRE11: #N/A
Name SegmentaciónDeDatos_TORRE111: #N/A
Name SegmentaciónDeDatos_TORRE1111: #N/A

Sheet BD_AVANCE
A1: TORRE | B1: N° MÓDULO | C1: N° SERIE | D1: TIPO | E1: % AVANCE | F1: FECHA INICIO TEORICO | G1: FECHA INICIO REAL | H1: FECHA ULTIMO REGISTRO | I1: FECHA TERMINO PLANIFICADO | J1: DIAS SIN MOVIMIENTO | K1: FECHA TERMINO | L1: APORTE OBRA GRUESA | M1: OBRA GRUESA | N1: PISO | O1: TABIQUES | P1: MUROS | Q1: CIELO | R1: BALCÓN | S1: APORTE SANITARIO | T1: SANITARIO | U1: RED ALCANTARILLADO | V1: RED DE AGUA | W1: VENTILACIONES | X1: TINA | Y1: WC | Z1: LAVAMANOS / LAVAPLATOS / LAVADERO | AA1: APORTE ELÉCTRICO | AB1: ELÉCTRICO | AC1: CANALIZACIÓN | AD1: CABLEADO | AE1: ARTEFACTOS | AF1: TABLERO | AG1: CAJA PAU | AH1: APORTE TERMINACIONES | AI1: TERMINACIONES | AJ1: INSTALACION VINILICO | AK1: OSB CUBIERTA | AL1: BARANDA BALCON | AM1: OSB EXTERIOR | AN1: SMART PANEL | AO1: PINTURA EXTERIOR | AP1: ZOCALOS LOGIA | AQ1: MOLDURAS | AR1: PILASTREO | AS1: CELOSIAS | AT1: VENTANAS | AU1: PUERTAS ACCESO - LOGIA - BANO | AV1: CERRADURAS | AW1: REVESTIMIENTO INTERIOR ZONA SECA | AX1: REVESTIMIENTO INTERIOR ZONAS HUMEDAS | AY1: MEMBRANA CIELO | AZ1: LIMPIEZA FINAL | BA1: PUERTAS DORMITORIO | BB1: REVESTIMIENTO INTERIOR BANO | BC1: MUEBLE LAVAPLATOS | BD1: IMPERMEABILIZACION BANO - COCINA LOGIA | BE1: METROS CUADRADOS | BF1: ESTADO MODULO | BG1: VENTANAS2 | BH1: PISO2 | BI1: TABIQUES2 | BJ1: MUROS2 | BK1: CIELO2 | BL1: BALCÓN2 | BM1: RED ALCANTARILLADO2 | BN1: RED DE AGUA2 | BO1: VENTILACIONES2 | BP1: TINA2 | BQ1: WC2 | BR1: LAVAMANOS / LAVAPLATOS / LAVADERO2 | BS1: CANALIZACIÓN2 | BT1: CABLEADO2 | BU1: ARTEFACTOS2 | BV1: TABLERO2 | BW1: CAJA PAU2 | BX1: INSTALACION VINILICO2 | BY1: OSB CUBIERTA3 | BZ1: BARANDA BALCON4 | CA1: OSB EXTERIOR5 | CB1: SMART PANEL6 | CC1: PINTURA EXTERIOR7 | CD1: ZOCALOS LOGIA8 | CE1: MOLDURAS9 | CF1: PILASTREO10 | CG1: CELOSIAS11 | CH1: VENTANAS12 | CI1: PUERTAS ACCESO - LOGIA - BANO13 | CJ1: CERRADURAS14 | CK1: REVESTIMIENTO INTERIOR ZONA SECA15 | CL1: REVESTIMIENTO INTERIOR ZONAS HUMEDAS16 | CM1: MEMBRANA CIELO17 | CN1: LIMPIEZA FINAL18 | CO1: PUERTAS DORMITORIO19 | CP1: REVESTIMIENTO INTERIOR BANO20 | CQ1: MUEBLE LAVAPLATOS21 | CR1: IMPERMEABILIZACION BANO - COCINA LOGIA22 | CS1: DIAS RETRASO | CT1: PARTIDAS PENDIENTES POR CATEGORÍA | CU1: CATEGORÍAS PENDIENTES | CV1: N° PENDIENTES
A2: TORRE 01 | B2: M-00001 | C2: 2282600001 | D2: SECO | E2: 1 | F2: 46097 | G2: 46097 | H2: 46153 | I2: 46140 | K2: 46153 | L2: 0.43 | M2: 1 | N2: 0.27906977 | O2: 0.18604651 | P2: 0.25581395 | Q2: 0.18604651 | R2: 0.093023256 | S2: 0.09 | T2: 1 | U2: 0.22222222 | V2: 0.22222222 | W2: 0.11111111 | X2: 0.11111111 | Y2: 0.11111111 | Z2: 0.22222222 | AA2: 0.11 | AB2: 1 | AC2: 0.27272727 | AD2: 0.27272727 | AE2: 0.090909091 | AF2: 0.18181818 | AG2: 0.18181818 | AH2: 0.37 | AI2: 1 | AJ2: 0.054054054 | AK2: 0.054054054 | AL2: 0.027027027 | AM2: 0.081081081 | AN2: 0.081081081 | AO2: 0.067567568 | AP2: 0.054054054 | AQ2: 0.013513514 | AR2: 0.040540541 | AS2: 0.013513514 | AT2: 0.081081081 | AU2: 0.054054054 | AV2: 0.027027027 | AW2: 0.054054054 | AX2: 0.054054054 | AY2: 0.027027027 | AZ2: 0.040540541 | BA2: 0.054054054 | BB2: 0.081081081 | BC2: 0.013513514 | BD2: 0.027027027 | BE2: 28.87 | BF2: =+IF(AVANCE[[#This Row],[% AVANCE]]=100%,"MODULO TERMINADO",IF(AVANCE[[#This Row],[FECHA INICIO REAL]]="","MODULO NO INICIADO","PENDIENTE")) -> MODULO TERMINADO | BG2: =+IF(AVANCE[[#This Row],[VENTANAS]]=8.10810810810811%,100%,AVANCE[[#This Row],[VENTANAS]]) -> 1 | BH2: =+IF(AVANCE[[#This Row],[PISO]]=N$2,100%,AVANCE[[#This Row],[PISO]]) -> 1 | BI2: =+IF(AVANCE[[#This Row],[TABIQUES]]=O$2,100%,AVANCE[[#This Row],[TABIQUES]]) -> 1 | BJ2: =+IF(AVANCE[[#This Row],[MUROS]]=P$2,100%,AVANCE[[#This Row],[MUROS]]) -> 1 | BK2: =+IF(AVANCE[[#This Row],[CIELO]]=Q$2,100%,AVANCE[[#This Row],[CIELO]]) -> 1 | BL2: =+IF(AVANCE[[#This Row],[BALCÓN]]=R$2,100%,AVANCE[[#This Row],[BALCÓN]]) -> 1 | BM2: =+IF(AVANCE[[#This Row],[RED ALCANTARILLADO]]=U$2,100%,AVANCE[[#This Row],[RED ALCANTARILLADO]]) -> 1 | BN2: =+IF(AVANCE[[#This Row],[RED DE AGUA]]=V$2,100%,AVANCE[[#This Row],[RED DE AGUA]]) -> 1 | BO2: =+IF(AVANCE[[#This Row],[VENTILACIONES]]=W$2,100%,AVANCE[[#This Row],[VENTILACIONES]]) -> 1 | BP2: =+IF(AVANCE[[#This Row],[TINA]]=X$2,100%,AVANCE[[#This Row],[TINA]]) -> 1 | BQ2: =+IF(AVANCE[[#This Row],[WC]]=Y$2,100%,AVANCE[[#This Row],[WC]]) -> 1 | BR2: =+IF(AVANCE[[#This Row],[LAVAMANOS / LAVAPLATOS / LAVADERO]]=Z$2,100%,AVANCE[[#This Row],[LAVAMANOS / LAVAPLATOS / LAVADERO]]) -> 1 | BS2: =+IF(AVANCE[[#This Row],[CANALIZACIÓN]]=AC$2,100%,AVANCE[[#This Row],[CANALIZACIÓN]]) -> 1 | BT2: =+IF(AVANCE[[#This Row],[CABLEADO]]=AD$2,100%,AVANCE[[#This Row],[CABLEADO]]) -> 1 | BU2: =+IF(AVANCE[[#This Row],[ARTEFACTOS]]=AE$2,100%,AVANCE[[#This Row],[ARTEFACTOS]]) -> 1 | BV2: =+IF(AVANCE[[#This Row],[TABLERO]]=AF$2,100%,AVANCE[[#This Row],[TABLERO]]) -> 1 | BW2: =+IF(AVANCE[[#This Row],[CAJA PAU]]=AG$2,100%,AVANCE[[#This Row],[CAJA PAU]]) -> 1 | BX2: =+IF(AVANCE[[#This Row],[INSTALACION VINILICO]]=AJ$2,100%,AVANCE[[#This Row],[INSTALACION VINILICO]]) -> 1 | BY2: =+IF(AVANCE[[#This Row],[OSB CUBIERTA]]=AK$2,100%,AVANCE[[#This Row],[OSB CUBIERTA]]) -> 1 | BZ2: =+IF(AVANCE[[#This Row],[BARANDA BALCON]]=AL$2,100%,AVANCE[[#This Row],[BARANDA BALCON]]) -> 1 | CA2: =+IF(AVANCE[[#This Row],[OSB EXTERIOR]]=AM$2,100%,AVANCE[[#This Row],[OSB EXTERIOR]]) -> 1 | CB2: =+IF(AVANCE[[#This Row],[SMART PANEL]]=AN$2,100%,AVANCE[[#This Row],[SMART PANEL]]) -> 1 | CC2: =+IF(AVANCE[[#This Row],[PINTURA EXTERIOR]]=AO$2,100%,AVANCE[[#This Row],[PINTURA EXTERIOR]]) -> 1 | CD2: =+IF(AVANCE[[#This Row],[ZOCALOS LOGIA]]=AP$2,100%,AVANCE[[#This Row],[ZOCALOS LOGIA]]) -> 1 | CE2: =+IF(AVANCE[[#This Row],[MOLDURAS]]=AQ$2,100%,AVANCE[[#This Row],[MOLDURAS]]) -> 1 | CF2: =+IF(AVANCE[[#This Row],[PILASTREO]]=AR$2,100%,AVANCE[[#This Row],[PILASTREO]]) -> 1 | CG2: =+IF(AVANCE[[#This Row],[CELOSIAS]]=AS$2,100%,AVANCE[[#This Row],[CELOSIAS]]) -> 1 | CH2: =+IF(AVANCE[[#This Row],[VENTANAS]]=AT$2,100%,AVANCE[[#This Row],[VENTANAS]]) -> 1 | CI2: =+IF(AVANCE[[#This Row],[PUERTAS ACCESO - LOGIA - BANO]]=AU$2,100%,AVANCE[[#This Row],[PUERTAS ACCESO - LOGIA - BANO]]) -> 1 | CJ2: =+IF(AVANCE[[#This Row],[CERRADURAS]]=AV$2,100%,AVANCE[[#This Row],[CERRADURAS]]) -> 1 | CK2: =+IF(AVANCE[[#This Row],[REVESTIMIENTO INTERIOR ZONA SECA]]=AW$2,100%,AVANCE[[#This Row],[REVESTIMIENTO INTERIOR ZONA SECA]]) -> 1 | CL2: =+IF(AVANCE[[#This Row],[REVESTIMIENTO INTERIOR ZONAS HUMEDAS]]=AX$2,100%,AVANCE[[#This Row],[REVESTIMIENTO INTERIOR ZONAS HUMEDAS]]) -> 1 | CM2: =+IF(AVANCE[[#This Row],[MEMBRANA CIELO]]=AY$2,100%,AVANCE[[#This Row],[MEMBRANA CIELO]]) -> 1 | CN2: =+IF(AVANCE[[#This Row],[LIMPIEZA FINAL]]=AZ$2,100%,AVANCE[[#This Row],[LIMPIEZA FINAL]]) -> 1 | CO2: =+IF(AVANCE[[#This Row],[PUERTAS DORMITORIO]]=BA$2,100%,AVANCE[[#This Row],[PUERTAS DORMITORIO]]) -> 1 | CP2: =+IF(AVANCE[[#This Row],[REVESTIMIENTO INTERIOR BANO]]=BB$2,100%,AVANCE[[#This Row],[REVESTIMIENTO INTERIOR BANO]]) -> 1 | CQ2: =+IF(AVANCE[[#This Row],[MUEBLE LAVAPLATOS]]=BC$2,100%,AVANCE[[#This Row],[MUEBLE LAVAPLATOS]]) -> 1 | CR2: =+IF(AVANCE[[#This Row],[IMPERMEABILIZACION BANO - COCINA LOGIA]]=BD$2,100%,AVANCE[[#This Row],[IMPERMEABILIZACION BANO - COCINA LOGIA]]) -> 1 | CS2: =+IF(AVANCE[[#This Row],[ESTADO MODULO]]="PENDIENTE",(TODAY()-AVANCE[[#This Row],[FECHA TERMINO PLANIFICADO]]),0) -> 0 | CT2: {=_xlfn.TEXTJOIN(" | ",TRUE,IF(SUMPRODUCT((BG2:CR2<1)*(PARTIDAS!$I$2:$AT$2="OBRA GRUESA"))>0,"OBRA GRUESA: "&_xlfn.TEXTJOIN(", ",TRUE,IF((BG2:CR2<1)*(PARTIDAS!$I$2:$AT$2="OBRA GRUESA"),PARTIDAS!$I$1:$AT$1,"")),""),IF(SUMPRODUCT((BG2:CR2<1)*(PARTIDAS!$I$2:$AT$2="SANITARIOS"))>0,"SANITARIOS: "&_xlfn.TEXTJOIN(", ",TRUE,IF((BG2:CR2<1)*(PARTIDAS!$I$2:$AT$2="SANITARIOS"),PARTIDAS!$I$1:$AT$1,"")),""),IF(SUMPRODUCT((BG2:CR2<1)*(PARTIDAS!$I$2:$AT$2="ELÉCTRICO"))>0,"ELÉCTRICO: "&_xlfn.TEXTJOIN(", ",TRUE,IF((BG2:CR2<1)*(PARTIDAS!$I$2:$AT$2="ELÉCTRICO"),PARTIDAS!$I$1:$AT$1,"")),""),IF(SUMPRODUCT((BG2:CR2<1)*(PARTIDAS!$I$2:$AT$2="TERMINACIONES"))>0,"TERMINACIONES: "&_xlfn.TEXTJOIN(", ",TRUE,IF((BG2:CR2<1)*(PARTIDAS!$I$2:$AT$2="TERMINACIONES"),PARTIDAS!$I$1:$AT$1,"")),""))} | CU2: {=_xlfn.TEXTJOIN(", ",TRUE,IF(SUMPRODUCT((BG2:CR2<1)*(PARTIDAS!$I$2:$AT$2="OBRA GRUESA"))>0,"OBRA GRUESA",""),IF(SUMPRODUCT((BG2:CR2<1)*(PARTIDAS!$I$2:$AT$2="SANITARIOS"))>0,"SANITARIOS",""),IF(SUMPRODUCT((BG2:CR2<1)*(PARTIDAS!$I$2:$AT$2="ELÉCTRICO"))>0,"ELÉCTRICO",""),IF(SUMPRODUCT((BG2:CR2<1)*(PARTIDAS!$I$2:$AT$2="TERMINACIONES"))>0,"TERMINACIONES",""))} | CV2: {=SUMPRODUCT(--(BG2:CR2<1))} -> 0
A3: TORRE 01 | B3: M-00002 | C3: 2302600002 | D3: HUMEDO | E3: 1 | F3: 46100 | G3: 46100 | H3: 46156 | I3: 46140 | K3: 46156 | L3: 0.43 | M3: 1 | N3: 0.27906977 | O3: 0.18604651 | P3: 0.25581395 | Q3: 0.18604651 | R3: 0.093023256 | S3: 0.09 | T3: 1 | U3: 0.22222222 | V3: 0.22222222 | W3: 0.11111111 | X3: 0.11111111 | Y3: 0.11111111 | Z3: 0.22222222 | AA3: 0.11 | AB3: 1 | AC3: 0.27272727 | AD3: 0.27272727 | AE3: 0.090909091 | AF3: 0.18181818 | AG3: 0.18181818 | AH3: 0.37 | AI3: 1 | AJ3: 0.054054054 | AK3: 0.054054054 | AL3: 0.027027027 | AM3: 0.081081081 | AN3: 0.081081081 | AO3: 0.067567568 | AP3: 0.054054054 | AQ3: 0.013513514 | AR3: 0.040540541 | AS3: 0.013513514 | AT3: 0.081081081 | AU3: 0.054054054 | AV3: 0.027027027 | AW3: 0.054054054 | AX3: 0.054054054 | AY3: 0.027027027 | AZ3: 0.040540541 | BA3: 0.054054054 | BB3: 0.081081081 | BC3: 0.013513514 | BD3: 0.027027027 | BE3: 31.32 | BF3: =+IF(AVANCE[[#This Row],[% AVANCE]]=100%,"MODULO TERMINADO",IF(AVANCE[[#This Row],[FECHA INICIO REAL]]="","MODULO NO INICIADO","PENDIENTE")) -> MODULO TERMINADO | BG3: =+IF(AVANCE[[#This Row],[VENTANAS]]=8.10810810810811%,100%,AVANCE[[#This Row],[VENTANAS]]) -> 1 | BH3: =+IF(AVANCE[[#This Row],[PISO]]=N$2,100%,AVANCE[[#This Row],[PISO]]) -> 1 | BI3: =+IF(AVANCE[[#This Row],[TABIQUES]]=O$2,100%,AVANCE[[#This Row],[TABIQUES]]) -> 1 | BJ3: =+IF(AVANCE[[#This Row],[MUROS]]=P$2,100%,AVANCE[[#This Row],[MUROS]]) -> 1 | BK3: =+IF(AVANCE[[#This Row],[CIELO]]=Q$2,100%,AVANCE[[#This Row],[CIELO]]) -> 1 | BL3: =+IF(AVANCE[[#This Row],[BALCÓN]]=R$2,100%,AVANCE[[#This Row],[BALCÓN]]) -> 1 | BM3: =+IF(AVANCE[[#This Row],[RED ALCANTARILLADO]]=U$2,100%,AVANCE[[#This Row],[RED ALCANTARILLADO]]) -> 1 | BN3: =+IF(AVANCE[[#This Row],[RED DE AGUA]]=V$2,100%,AVANCE[[#This Row],[RED DE AGUA]]) -> 1 | BO3: =+IF(AVANCE[[#This Row],[VENTILACIONES]]=W$2,100%,AVANCE[[#This Row],[VENTILACIONES]]) -> 1 | BP3: =+IF(AVANCE[[#This Row],[TINA]]=X$2,100%,AVANCE[[#This Row],[TINA]]) -> 1 | BQ3: =+IF(AVANCE[[#This Row],[WC]]=Y$2,100%,AVANCE[[#This Row],[WC]]) -> 1 | BR3: =+IF(AVANCE[[#This Row],[LAVAMANOS / LAVAPLATOS / LAVADERO]]=Z$2,100%,AVANCE[[#This Row],[LAVAMANOS / LAVAPLATOS / LAVADERO]]) -> 1 | BS3: =+IF(AVANCE[[#This Row],[CANALIZACIÓN]]=AC$2,100%,AVANCE[[#This Row],[CANALIZACIÓN]]) -> 1 | BT3: =+IF(AVANCE[[#This Row],[CABLEADO]]=AD$2,100%,AVANCE[[#This Row],[CABLEADO]]) -> 1 | BU3: =+IF(AVANCE[[#This Row],[ARTEFACTOS]]=AE$2,100%,AVANCE[[#This Row],[ARTEFACTOS]]) -> 1 | BV3: =+IF(AVANCE[[#This Row],[TABLERO]]=AF$2,100%,AVANCE[[#This Row],[TABLERO]]) -> 1 | BW3: =+IF(AVANCE[[#This Row],[CAJA PAU]]=AG$2,100%,AVANCE[[#This Row],[CAJA PAU]]) -> 1 | BX3: =+IF(AVANCE[[#This Row],[INSTALACION VINILICO]]=AJ$2,100%,AVANCE[[#This Row],[INSTALACION VINILICO]]) -> 1 | BY3: =+IF(AVANCE[[#This Row],[OSB CUBIERTA]]=AK$2,100%,AVANCE[[#This Row],[OSB CUBIERTA]]) -> 1 | BZ3: =+IF(AVANCE[[#This Row],[BARANDA BALCON]]=AL$2,100%,AVANCE[[#This Row],[BARANDA BALCON]]) -> 1 | CA3: =+IF(AVANCE[[#This Row],[OSB EXTERIOR]]=AM$2,100%,AVANCE[[#This Row],[OSB EXTERIOR]]) -> 1 | CB3: =+IF(AVANCE[[#This Row],[SMART PANEL]]=AN$2,100%,AVANCE[[#This Row],[SMART PANEL]]) -> 1 | CC3: =+IF(AVANCE[[#This Row],[PINTURA EXTERIOR]]=AO$2,100%,AVANCE[[#This Row],[PINTURA EXTERIOR]]) -> 1 | CD3: =+IF(AVANCE[[#This Row],[ZOCALOS LOGIA]]=AP$2,100%,AVANCE[[#This Row],[ZOCALOS LOGIA]]) -> 1 | CE3: =+IF(AVANCE[[#This Row],[MOLDURAS]]=AQ$2,100%,AVANCE[[#This Row],[MOLDURAS]]) -> 1 | CF3: =+IF(AVANCE[[#This Row],[PILASTREO]]=AR$2,100%,AVANCE[[#This Row],[PILASTREO]]) -> 1 | CG3: =+IF(AVANCE[[#This Row],[CELOSIAS]]=AS$2,100%,AVANCE[[#This Row],[CELOSIAS]]) -> 1 | CH3: =+IF(AVANCE[[#This Row],[VENTANAS]]=AT$2,100%,AVANCE[[#This Row],[VENTANAS]]) -> 1 | CI3: =+IF(AVANCE[[#This Row],[PUERTAS ACCESO - LOGIA - BANO]]=AU$2,100%,AVANCE[[#This Row],[PUERTAS ACCESO - LOGIA - BANO]]) -> 1 | CJ3: =+IF(AVANCE[[#This Row],[CERRADURAS]]=AV$2,100%,AVANCE[[#This Row],[CERRADURAS]]) -> 1 | CK3: =+IF(AVANCE[[#This Row],[REVESTIMIENTO INTERIOR ZONA SECA]]=AW$2,100%,AVANCE[[#This Row],[REVESTIMIENTO INTERIOR ZONA SECA]]) -> 1 | CL3: =+IF(AVANCE[[#This Row],[REVESTIMIENTO INTERIOR ZONAS HUMEDAS]]=AX$2,100%,AVANCE[[#This Row],[REVESTIMIENTO INTERIOR ZONAS HUMEDAS]]) -> 1 | CM3: =+IF(AVANCE[[#This Row],[MEMBRANA CIELO]]=AY$2,100%,AVANCE[[#This Row],[MEMBRANA CIELO]]) -> 1 | CN3: =+IF(AVANCE[[#This Row],[LIMPIEZA FINAL]]=AZ$2,100%,AVANCE[[#This Row],[LIMPIEZA FINAL]]) -> 1 | CO3: =+IF(AVANCE[[#This Row],[PUERTAS DORMITORIO]]=BA$2,100%,AVANCE[[#This Row],[PUERTAS DORMITORIO]]) -> 1 | CP3: =+IF(AVANCE[[#This Row],[REVESTIMIENTO INTERIOR BANO]]=BB$2,100%,AVANCE[[#This Row],[REVESTIMIENTO INTERIOR BANO]]) -> 1 | CQ3: =+IF(AVANCE[[#This Row],[MUEBLE LAVAPLATOS]]=BC$2,100%,AVANCE[[#This Row],[MUEBLE LAVAPLATOS]]) -> 1 | CR3: =+IF(AVANCE[[#This Row],[IMPERMEABILIZACION BANO - COCINA LOGIA]]=BD$2,100%,AVANCE[[#This Row],[IMPERMEABILIZACION BANO - COCINA LOGIA]]) -> 1 | CS3: =+IF(AVANCE[[#This Row],[ESTADO MODULO]]="PENDIENTE",(TODAY()-AVANCE[[#This Row],[FECHA TERMINO PLANIFICADO]]),0) -> 0 | CT3: {=_xlfn.TEXTJOIN(" | ",TRUE,IF(SUMPRODUCT((BG3:CR3<1)*(PARTIDAS!$I$2:$AT$2="OBRA GRUESA"))>0,"OBRA GRUESA: "&_xlfn.TEXTJOIN(", ",TRUE,IF((BG3:CR3<1)*(PARTIDAS!$I$2:$AT$2="OBRA GRUESA"),PARTIDAS!$I$1:$AT$1,"")),""),IF(SUMPRODUCT((BG3:CR3<1)*(PARTIDAS!$I$2:$AT$2="SANITARIOS"))>0,"SANITARIOS: "&_xlfn.TEXTJOIN(", ",TRUE,IF((BG3:CR3<1)*(PARTIDAS!$I$2:$AT$2="SANITARIOS"),PARTIDAS!$I$1:$AT$1,"")),""),IF(SUMPRODUCT((BG3:CR3<1)*(PARTIDAS!$I$2:$AT$2="ELÉCTRICO"))>0,"ELÉCTRICO: "&_xlfn.TEXTJOIN(", ",TRUE,IF((BG3:CR3<1)*(PARTIDAS!$I$2:$AT$2="ELÉCTRICO"),PARTIDAS!$I$1:$AT$1,"")),""),IF(SUMPRODUCT((BG3:CR3<1)*(PARTIDAS!$I$2:$AT$2="TERMINACIONES"))>0,"TERMINACIONES: "&_xlfn.TEXTJOIN(", ",TRUE,IF((BG3:CR3<1)*(PARTIDAS!$I$2:$AT$2="TERMINACIONES"),PARTIDAS!$I$1:$AT$1,"")),""))} | CU3: {=_xlfn.TEXTJOIN(", ",TRUE,IF(SUMPRODUCT((BG3:CR3<1)*(PARTIDAS!$I$2:$AT$2="OBRA GRUESA"))>0,"OBRA GRUESA",""),IF(SUMPRODUCT((BG3:CR3<1)*(PARTIDAS!$I$2:$AT$2="SANITARIOS"))>0,"SANITARIOS",""),IF(SUMPRODUCT((BG3:CR3<1)*(PARTIDAS!$I$2:$AT$2="ELÉCTRICO"))>0,"ELÉCTRICO",""),IF(SUMPRODUCT((BG3:CR3<1)*(PARTIDAS!$I$2:$AT$2="TERMINACIONES"))>0,"TERMINACIONES",""))} | CV3: {=SUMPRODUCT(--(BG3:CR3<1))} -> 0
A4: TORRE 01 | B4: M-00003 | C4: 2302600003 | D4: HUMEDO | E4: 1 | F4: 46099 | G4: 46099 | H4: 46160 | I4: 46147 | K4: 46160 | L4: 0.43 | M4: 1 | N4: 0.27906977 | O4: 0.18604651 | P4: 0.25581395 | Q4: 0.18604651 | R4: 0.093023256 | S4: 0.09 | T4: 1 | U4: 0.22222222 | V4: 0.22222222 | W4: 0.11111111 | X4: 0.11111111 | Y4: 0.11111111 | Z4: 0.22222222 | AA4: 0.11 | AB4: 1 | AC4: 0.27272727 | AD4: 0.27272727 | AE4: 0.090909091 | AF4: 0.18181818 | AG4: 0.18181818 | AH4: 0.37 | AI4: 1 | AJ4: 0.054054054 | AK4: 0.054054054 | AL4: 0.027027027 | AM4: 0.081081081 | AN4: 0.081081081 | AO4: 0.067567568 | AP4: 0.054054054 | AQ4: 0.013513514 | AR4: 0.040540541 | AS4: 0.013513514 | AT4: 0.081081081 | AU4: 0.054054054 | AV4: 0.027027027 | AW4: 0.054054054 | AX4: 0.054054054 | AY4: 0.027027027 | AZ4: 0.040540541 | BA4: 0.054054054 | BB4: 0.081081081 | BC4: 0.013513514 | BD4: 0.027027027 | BE4: 31.32 | BF4: =+IF(AVANCE[[#This Row],[% AVANCE]]=100%,"MODULO TERMINADO",IF(AVANCE[[#This Row],[FECHA INICIO REAL]]="","MODULO NO INICIADO","PENDIENTE")) -> MODULO TERMINADO | BG4: =+IF(AVANCE[[#This Row],[VENTANAS]]=8.10810810810811%,100%,AVANCE[[#This Row],[VENTANAS]]) -> 1 | BH4: =+IF(AVANCE[[#This Row],[PISO]]=N$2,100%,AVANCE[[#This Row],[PISO]]) -> 1 | BI4: =+IF(AVANCE[[#This Row],[TABIQUES]]=O$2,100%,AVANCE[[#This Row],[TABIQUES]]) -> 1 | BJ4: =+IF(AVANCE[[#This Row],[MUROS]]=P$2,100%,AVANCE[[#This Row],[MUROS]]) -> 1 | BK4: =+IF(AVANCE[[#This Row],[CIELO]]=Q$2,100%,AVANCE[[#This Row],[CIELO]]) -> 1 | BL4: =+IF(AVANCE[[#This Row],[BALCÓN]]=R$2,100%,AVANCE[[#This Row],[BALCÓN]]) -> 1 | BM4: =+IF(AVANCE[[#This Row],[RED ALCANTARILLADO]]=U$2,100%,AVANCE[[#This Row],[RED ALCANTARILLADO]]) -> 1 | BN4: =+IF(AVANCE[[#This Row],[RED DE AGUA]]=V$2,100%,AVANCE[[#This Row],[RED DE AGUA]]) -> 1 | BO4: =+IF(AVANCE[[#This Row],[VENTILACIONES]]=W$2,100%,AVANCE[[#This Row],[VENTILACIONES]]) -> 1 | BP4: =+IF(AVANCE[[#This Row],[TINA]]=X$2,100%,AVANCE[[#This Row],[TINA]]) -> 1 | BQ4: =+IF(AVANCE[[#This Row],[WC]]=Y$2,100%,AVANCE[[#This Row],[WC]]) -> 1 | BR4: =+IF(AVANCE[[#This Row],[LAVAMANOS / LAVAPLATOS / LAVADERO]]=Z$2,100%,AVANCE[[#This Row],[LAVAMANOS / LAVAPLATOS / LAVADERO]]) -> 1 | BS4: =+IF(AVANCE[[#This Row],[CANALIZACIÓN]]=AC$2,100%,AVANCE[[#This Row],[CANALIZACIÓN]]) -> 1 | BT4: =+IF(AVANCE[[#This Row],[CABLEADO]]=AD$2,100%,AVANCE[[#This Row],[CABLEADO]]) -> 1 | BU4: =+IF(AVANCE[[#This Row],[ARTEFACTOS]]=AE$2,100%,AVANCE[[#This Row],[ARTEFACTOS]]) -> 1 | BV4: =+IF(AVANCE[[#This Row],[TABLERO]]=AF$2,100%,AVANCE[[#This Row],[TABLERO]]) -> 1 | BW4: =+IF(AVANCE[[#This Row],[CAJA PAU]]=AG$2,100%,AVANCE[[#This Row],[CAJA PAU]]) -> 1 | BX4: =+IF(AVANCE[[#This Row],[INSTALACION VINILICO]]=AJ$2,100%,AVANCE[[#This Row],[INSTALACION VINILICO]]) -> 1 | BY4: =+IF(AVANCE[[#This Row],[OSB CUBIERTA]]=AK$2,100%,AVANCE[[#This Row],[OSB CUBIERTA]]) -> 1 | BZ4: =+IF(AVANCE[[#This Row],[BARANDA BALCON]]=AL$2,100%,AVANCE[[#This Row],[BARANDA BALCON]]) -> 1 | CA4: =+IF(AVANCE[[#This Row],[OSB EXTERIOR]]=AM$2,100%,AVANCE[[#This Row],[OSB EXTERIOR]]) -> 1 | CB4: =+IF(AVANCE[[#This Row],[SMART PANEL]]=AN$2,100%,AVANCE[[#This Row],[SMART PANEL]]) -> 1 | CC4: =+IF(AVANCE[[#This Row],[PINTURA EXTERIOR]]=AO$2,100%,AVANCE[[#This Row],[PINTURA EXTERIOR]]) -> 1 | CD4: =+IF(AVANCE[[#This Row],[ZOCALOS LOGIA]]=AP$2,100%,AVANCE[[#This Row],[ZOCALOS LOGIA]]) -> 1 | CE4: =+IF(AVANCE[[#This Row],[MOLDURAS]]=AQ$2,100%,AVANCE[[#This Row],[MOLDURAS]]) -> 1 | CF4: =+IF(AVANCE[[#This Row],[PILASTREO]]=AR$2,100%,AVANCE[[#This Row],[PILASTREO]]) -> 1 | CG4: =+IF(AVANCE[[#This Row],[CELOSIAS]]=AS$2,100%,AVANCE[[#This Row],[CELOSIAS]]) -> 1 | CH4: =+IF(AVANCE[[#This Row],[VENTANAS]]=AT$2,100%,AVANCE[[#This Row],[VENTANAS]]) -> 1 | CI4: =+IF(AVANCE[[#This Row],[PUERTAS ACCESO - LOGIA - BANO]]=AU$2,100%,AVANCE[[#This Row],[PUERTAS ACCESO - LOGIA - BANO]]) -> 1 | CJ4: =+IF(AVANCE[[#This Row],[CERRADURAS]]=AV$2,100%,AVANCE[[#This Row],[CERRADURAS]]) -> 1 | CK4: =+IF(AVANCE[[#This Row],[REVESTIMIENTO INTERIOR ZONA SECA]]=AW$2,100%,AVANCE[[#This Row],[REVESTIMIENTO INTERIOR ZONA SECA]]) -> 1 | CL4: =+IF(AVANCE[[#This Row],[REVESTIMIENTO INTERIOR ZONAS HUMEDAS]]=AX$2,100%,AVANCE[[#This Row],[REVESTIMIENTO INTERIOR ZONAS HUMEDAS]]) -> 1 | CM4: =+IF(AVANCE[[#This Row],[MEMBRANA CIELO]]=AY$2,100%,AVANCE[[#This Row],[MEMBRANA CIELO]]) -> 1 | CN4: =+IF(AVANCE[[#This Row],[LIMPIEZA FINAL]]=AZ$2,100%,AVANCE[[#This Row],[LIMPIEZA FINAL]]) -> 1 | CO4: =+IF(AVANCE[[#This Row],[PUERTAS DORMITORIO]]=BA$2,100%,AVANCE[[#This Row],[PUERTAS DORMITORIO]]) -> 1 | CP4: =+IF(AVANCE[[#This Row],[REVESTIMIENTO INTERIOR BANO]]=BB$2,100%,AVANCE[[#This Row],[REVESTIMIENTO INTERIOR BANO]]) -> 1 | CQ4: =+IF(AVANCE[[#This Row],[MUEBLE LAVAPLATOS]]=BC$2,100%,AVANCE[[#This Row],[MUEBLE LAVAPLATOS]]) -> 1 | CR4: =+IF(AVANCE[[#This Row],[IMPERMEABILIZACION BANO - COCINA LOGIA]]=BD$2,100%,AVANCE[[#This Row],[IMPERMEABILIZACION BANO - COCINA LOGIA]]) -> 1 | CS4: =+IF(AVANCE[[#This Row],[ESTADO MODULO]]="PENDIENTE",(TODAY()-AVANCE[[#This Row],[FECHA TERMINO PLANIFICADO]]),0) -> 0 | CT4: {=_xlfn.TEXTJOIN(" | ",TRUE,IF(SUMPRODUCT((BG4:CR4<1)*(PARTIDAS!$I$2:$AT$2="OBRA GRUESA"))>0,"OBRA GRUESA: "&_xlfn.TEXTJOIN(", ",TRUE,IF((BG4:CR4<1)*(PARTIDAS!$I$2:$AT$2="OBRA GRUESA"),PARTIDAS!$I$1:$AT$1,"")),""),IF(SUMPRODUCT((BG4:CR4<1)*(PARTIDAS!$I$2:$AT$2="SANITARIOS"))>0,"SANITARIOS: "&_xlfn.TEXTJOIN(", ",TRUE,IF((BG4:CR4<1)*(PARTIDAS!$I$2:$AT$2="SANITARIOS"),PARTIDAS!$I$1:$AT$1,"")),""),IF(SUMPRODUCT((BG4:CR4<1)*(PARTIDAS!$I$2:$AT$2="ELÉCTRICO"))>0,"ELÉCTRICO: "&_xlfn.TEXTJOIN(", ",TRUE,IF((BG4:CR4<1)*(PARTIDAS!$I$2:$AT$2="ELÉCTRICO"),PARTIDAS!$I$1:$AT$1,"")),""),IF(SUMPRODUCT((BG4:CR4<1)*(PARTIDAS!$I$2:$AT$2="TERMINACIONES"))>0,"TERMINACIONES: "&_xlfn.TEXTJOIN(", ",TRUE,IF((BG4:CR4<1)*(PARTIDAS!$I$2:$AT$2="TERMINACIONES"),PARTIDAS!$I$1:$AT$1,"")),""))} | CU4: {=_xlfn.TEXTJOIN(", ",TRUE,IF(SUMPRODUCT((BG4:CR4<1)*(PARTIDAS!$I$2:$AT$2="OBRA GRUESA"))>0,"OBRA GRUESA",""),IF(SUMPRODUCT((BG4:CR4<1)*(PARTIDAS!$I$2:$AT$2="SANITARIOS"))>0,"SANITARIOS",""),IF(SUMPRODUCT((BG4:CR4<1)*(PARTIDAS!$I$2:$AT$2="ELÉCTRICO"))>0,"ELÉCTRICO",""),IF(SUMPRODUCT((BG4:CR4<1)*(PARTIDAS!$I$2:$AT$2="TERMINACIONES"))>0,"TERMINACIONES",""))} | CV4: {=SUMPRODUCT(--(BG4:CR4<1))} -> 0
A5: TORRE 01 | B5: M-00004 | C5: 2282600004 | D5: SECO | E5: 1 | F5: 46093 | G5: 46093 | H5: 46156 | I5: 46142 | K5: 46156 | L5: 0.43 | M5: 1 | N5: 0.27906977 | O5: 0.18604651 | P5: 0.25581395 | Q5: 0.18604651 | R5: 0.093023256 | S5: 0.09 | T5: 1 | U5: 0.22222222 | V5: 0.22222222 | W5: 0.11111111 | X5: 0.11111111 | Y5: 0.11111111 | Z5: 0.22222222 | AA5: 0.11 | AB5: 1 | AC5: 0.27272727 | AD5: 0.27272727 | AE5: 0.090909091 | AF5: 0.18181818 | AG5: 0.18181818 | AH5: 0.37 | AI5: 1 | AJ5: 0.054054054 | AK5: 0.054054054 | AL5: 0.027027027 | AM5: 0.081081081 | AN5: 0.081081081 | AO5: 0.067567568 | AP5: 0.054054054 | AQ5: 0.013513514 | AR5: 0.040540541 | AS5: 0.013513514 | AT5: 0.081081081 | AU5: 0.054054054 | AV5: 0.027027027 | AW5: 0.054054054 | AX5: 0.054054054 | AY5: 0.027027027 | AZ5: 0.040540541 | BA5: 0.054054054 | BB5: 0.081081081 | BC5: 0.013513514 | BD5: 0.027027027 | BE5: 28.87 | BF5: =+IF(AVANCE[[#This Row],[% AVANCE]]=100%,"MODULO TERMINADO",IF(AVANCE[[#This Row],[FECHA INICIO REAL]]="","MODULO NO INICIADO","PENDIENTE")) -> MODULO TERMINADO | BG5: =+IF(AVANCE[[#This Row],[VENTANAS]]=8.10810810810811%,100%,AVANCE[[#This Row],[VENTANAS]]) -> 1 | BH5: =+IF(AVANCE[[#This Row],[PISO]]=N$2,100%,AVANCE[[#This Row],[PISO]]) -> 1 | BI5: =+IF(AVANCE[[#This Row],[TABIQUES]]=O$2,100%,AVANCE[[#This Row],[TABIQUES]]) -> 1 | BJ5: =+IF(AVANCE[[#This Row],[MUROS]]=P$2,100%,AVANCE[[#This Row],[MUROS]]) -> 1 | BK5: =+IF(AVANCE[[#This Row],[CIELO]]=Q$2,100%,AVANCE[[#This Row],[CIELO]]) -> 1 | BL5: =+IF(AVANCE[[#This Row],[BALCÓN]]=R$2,100%,AVANCE[[#This Row],[BALCÓN]]) -> 1 | BM5: =+IF(AVANCE[[#This Row],[RED ALCANTARILLADO]]=U$2,100%,AVANCE[[#This Row],[RED ALCANTARILLADO]]) -> 1 | BN5: =+IF(AVANCE[[#This Row],[RED DE AGUA]]=V$2,100%,AVANCE[[#This Row],[RED DE AGUA]]) -> 1 | BO5: =+IF(AVANCE[[#This Row],[VENTILACIONES]]=W$2,100%,AVANCE[[#This Row],[VENTILACIONES]]) -> 1 | BP5: =+IF(AVANCE[[#This Row],[TINA]]=X$2,100%,AVANCE[[#This Row],[TINA]]) -> 1 | BQ5: =+IF(AVANCE[[#This Row],[WC]]=Y$2,100%,AVANCE[[#This Row],[WC]]) -> 1 | BR5: =+IF(AVANCE[[#This Row],[LAVAMANOS / LAVAPLATOS / LAVADERO]]=Z$2,100%,AVANCE[[#This Row],[LAVAMANOS / LAVAPLATOS / LAVADERO]]) -> 1 | BS5: =+IF(AVANCE[[#This Row],[CANALIZACIÓN]]=AC$2,100%,AVANCE[[#This Row],[CANALIZACIÓN]]) -> 1 | BT5: =+IF(AVANCE[[#This Row],[CABLEADO]]=AD$2,100%,AVANCE[[#This Row],[CABLEADO]]) -> 1 | BU5: =+IF(AVANCE[[#This Row],[ARTEFACTOS]]=AE$2,100%,AVANCE[[#This Row],[ARTEFACTOS]]) -> 1 | BV5: =+IF(AVANCE[[#This Row],[TABLERO]]=AF$2,100%,AVANCE[[#This Row],[TABLERO]]) -> 1 | BW5: =+IF(AVANCE[[#This Row],[CAJA PAU]]=AG$2,100%,AVANCE[[#This Row],[CAJA PAU]]) -> 1 | BX5: =+IF(AVANCE[[#This Row],[INSTALACION VINILICO]]=AJ$2,100%,AVANCE[[#This Row],[INSTALACION VINILICO]]) -> 1 | BY5: =+IF(AVANCE[[#This Row],[OSB CUBIERTA]]=AK$2,100%,AVANCE[[#This Row],[OSB CUBIERTA]]) -> 1 | BZ5: =+IF(AVANCE[[#This Row],[BARANDA BALCON]]=AL$2,100%,AVANCE[[#This Row],[BARANDA BALCON]]) -> 1 | CA5: =+IF(AVANCE[[#This Row],[OSB EXTERIOR]]=AM$2,100%,AVANCE[[#This Row],[OSB EXTERIOR]]) -> 1 | CB5: =+IF(AVANCE[[#This Row],[SMART PANEL]]=AN$2,100%,AVANCE[[#This Row],[SMART PANEL]]) -> 1 | CC5: =+IF(AVANCE[[#This Row],[PINTURA EXTERIOR]]=AO$2,100%,AVANCE[[#This Row],[PINTURA EXTERIOR]]) -> 1 | CD5: =+IF(AVANCE[[#This Row],[ZOCALOS LOGIA]]=AP$2,100%,AVANCE[[#This Row],[ZOCALOS LOGIA]]) -> 1 | CE5: =+IF(AVANCE[[#This Row],[MOLDURAS]]=AQ$2,100%,AVANCE[[#This Row],[MOLDURAS]]) -> 1 | CF5: =+IF(AVANCE[[#This Row],[PILASTREO]]=AR$2,100%,AVANCE[[#This Row],[PILASTREO]]) -> 1 | CG5: =+IF(AVANCE[[#This Row],[CELOSIAS]]=AS$2,100%,AVANCE[[#This Row],[CELOSIAS]]) -> 1 | CH5: =+IF(AVANCE[[#This Row],[VENTANAS]]=AT$2,100%,AVANCE[[#This Row],[VENTANAS]]) -> 1 | CI5: =+IF(AVANCE[[#This Row],[PUERTAS ACCESO - LOGIA - BANO]]=AU$2,100%,AVANCE[[#This Row],[PUERTAS ACCESO - LOGIA - BANO]]) -> 1 | CJ5: =+IF(AVANCE[[#This Row],[CERRADURAS]]=AV$2,100%,AVANCE[[#This Row],[CERRADURAS]]) -> 1 | CK5: =+IF(AVANCE[[#This Row],[REVESTIMIENTO INTERIOR ZONA SECA]]=AW$2,100%,AVANCE[[#This Row],[REVESTIMIENTO INTERIOR ZONA SECA]]) -> 1 | CL5: =+IF(AVANCE[[#This Row],[REVESTIMIENTO INTERIOR ZONAS HUMEDAS]]=AX$2,100%,AVANCE[[#This Row],[REVESTIMIENTO INTERIOR ZONAS HUMEDAS]]) -> 1 | CM5: =+IF(AVANCE[[#This Row],[MEMBRANA CIELO]]=AY$2,100%,AVANCE[[#This Row],[MEMBRANA CIELO]]) -> 1 | CN5: =+IF(AVANCE[[#This Row],[LIMPIEZA FINAL]]=AZ$2,100%,AVANCE[[#This Row],[LIMPIEZA FINAL]]) -> 1 | CO5: =+IF(AVANCE[[#This Row],[PUERTAS DORMITORIO]]=BA$2,100%,AVANCE[[#This Row],[PUERTAS DORMITORIO]]) -> 1 | CP5: =+IF(AVANCE[[#This Row],[REVESTIMIENTO INTERIOR BANO]]=BB$2,100%,AVANCE[[#This Row],[REVESTIMIENTO INTERIOR BANO]]) -> 1 | CQ5: =+IF(AVANCE[[#This Row],[MUEBLE LAVAPLATOS]]=BC$2,100%,AVANCE[[#This Row],[MUEBLE LAVAPLATOS]]) -> 1 | CR5: =+IF(AVANCE[[#This Row],[IMPERMEABILIZACION BANO - COCINA LOGIA]]=BD$2,100%,AVANCE[[#This Row],[IMPERMEABILIZACION BANO - COCINA LOGIA]]) -> 1 | CS5: =+IF(AVANCE[[#This Row],[ESTADO MODULO]]="PENDIENTE",(TODAY()-AVANCE[[#This Row],[FECHA TERMINO PLANIFICADO]]),0) -> 0 | CT5: {=_xlfn.TEXTJOIN(" | ",TRUE,IF(SUMPRODUCT((BG5:CR5<1)*(PARTIDAS!$I$2:$AT$2="OBRA GRUESA"))>0,"OBRA GRUESA: "&_xlfn.TEXTJOIN(", ",TRUE,IF((BG5:CR5<1)*(PARTIDAS!$I$2:$AT$2="OBRA GRUESA"),PARTIDAS!$I$1:$AT$1,"")),""),IF(SUMPRODUCT((BG5:CR5<1)*(PARTIDAS!$I$2:$AT$2="SANITARIOS"))>0,"SANITARIOS: "&_xlfn.TEXTJOIN(", ",TRUE,IF((BG5:CR5<1)*(PARTIDAS!$I$2:$AT$2="SANITARIOS"),PARTIDAS!$I$1:$AT$1,"")),""),IF(SUMPRODUCT((BG5:CR5<1)*(PARTIDAS!$I$2:$AT$2="ELÉCTRICO"))>0,"ELÉCTRICO: "&_xlfn.TEXTJOIN(", ",TRUE,IF((BG5:CR5<1)*(PARTIDAS!$I$2:$AT$2="ELÉCTRICO"),PARTIDAS!$I$1:$AT$1,"")),""),IF(SUMPRODUCT((BG5:CR5<1)*(PARTIDAS!$I$2:$AT$2="TERMINACIONES"))>0,"TERMINACIONES: "&_xlfn.TEXTJOIN(", ",TRUE,IF((BG5:CR5<1)*(PARTIDAS!$I$2:$AT$2="TERMINACIONES"),PARTIDAS!$I$1:$AT$1,"")),""))} | CU5: {=_xlfn.TEXTJOIN(", ",TRUE,IF(SUMPRODUCT((BG5:CR5<1)*(PARTIDAS!$I$2:$AT$2="OBRA GRUESA"))>0,"OBRA GRUESA",""),IF(SUMPRODUCT((BG5:CR5<1)*(PARTIDAS!$I$2:$AT$2="SANITARIOS"))>0,"SANITARIOS",""),IF(SUMPRODUCT((BG5:CR5<1)*(PARTIDAS!$I$2:$AT$2="ELÉCTRICO"))>0,"ELÉCTRICO",""),IF(SUMPRODUCT((BG5:CR5<1)*(PARTIDAS!$I$2:$AT$2="TERMINACIONES"))>0,"TERMINACIONES",""))} | CV5: {=SUMPRODUCT(--(BG5:CR5<1))} -> 0
A6: TORRE 01 | B6: M-00005 | C6: 2282600005 | D6: SECO | E6: 1 | F6: 46104 | G6: 46104 | H6: 46150 | I6: 46147 | K6: 46150 | L6: 0.43 | M6: 1 | N6: 0.27906977 | O6: 0.18604651 | P6: 0.25581395 | Q6: 0.18604651 | R6: 0.093023256 | S6: 0.09 | T6: 1 | U6: 0.22222222 | V6: 0.22222222 | W6: 0.11111111 | X6: 0.11111111 | Y6: 0.11111111 | Z6: 0.22222222 | AA6: 0.11 | AB6: 1 | AC6: 0.27272727 | AD6: 0.27272727 | AE6: 0.090909091 | AF6: 0.18181818 | AG6: 0.18181818 | AH6: 0.37 | AI6: 1 | AJ6: 0.054054054 | AK6: 0.054054054 | AL6: 0.027027027 | AM6: 0.081081081 | AN6: 0.081081081 | AO6: 0.067567568 | AP6: 0.054054054 | AQ6: 0.013513514 | AR6: 0.040540541 | AS6: 0.013513514 | AT6: 0.081081081 | AU6: 0.054054054 | AV6: 0.027027027 | AW6: 0.054054054 | AX6: 0.054054054 | AY6: 0.027027027 | AZ6: 0.040540541 | BA6: 0.054054054 | BB6: 0.081081081 | BC6: 0.013513514 | BD6: 0.027027027 | BE6: 28.87 | BF6: =+IF(AVANCE[[#This Row],[% AVANCE]]=100%,"MODULO TERMINADO",IF(AVANCE[[#This Row],[FECHA INICIO REAL]]="","MODULO NO INICIADO","PENDIENTE")) -> MODULO TERMINADO | BG6: =+IF(AVANCE[[#This Row],[VENTANAS]]=8.10810810810811%,100%,AVANCE[[#This Row],[VENTANAS]]) -> 1 | BH6: =+IF(AVANCE[[#This Row],[PISO]]=N$2,100%,AVANCE[[#This Row],[PISO]]) -> 1 | BI6: =+IF(AVANCE[[#This Row],[TABIQUES]]=O$2,100%,AVANCE[[#This Row],[TABIQUES]]) -> 1 | BJ6: =+IF(AVANCE[[#This Row],[MUROS]]=P$2,100%,AVANCE[[#This Row],[MUROS]]) -> 1 | BK6: =+IF(AVANCE[[#This Row],[CIELO]]=Q$2,100%,AVANCE[[#This Row],[CIELO]]) -> 1 | BL6: =+IF(AVANCE[[#This Row],[BALCÓN]]=R$2,100%,AVANCE[[#This Row],[BALCÓN]]) -> 1 | BM6: =+IF(AVANCE[[#This Row],[RED ALCANTARILLADO]]=U$2,100%,AVANCE[[#This Row],[RED ALCANTARILLADO]]) -> 1 | BN6: =+IF(AVANCE[[#This Row],[RED DE AGUA]]=V$2,100%,AVANCE[[#This Row],[RED DE AGUA]]) -> 1 | BO6: =+IF(AVANCE[[#This Row],[VENTILACIONES]]=W$2,100%,AVANCE[[#This Row],[VENTILACIONES]]) -> 1 | BP6: =+IF(AVANCE[[#This Row],[TINA]]=X$2,100%,AVANCE[[#This Row],[TINA]]) -> 1 | BQ6: =+IF(AVANCE[[#This Row],[WC]]=Y$2,100%,AVANCE[[#This Row],[WC]]) -> 1 | BR6: =+IF(AVANCE[[#This Row],[LAVAMANOS / LAVAPLATOS / LAVADERO]]=Z$2,100%,AVANCE[[#This Row],[LAVAMANOS / LAVAPLATOS / LAVADERO]]) -> 1 | BS6: =+IF(AVANCE[[#This Row],[CANALIZACIÓN]]=AC$2,100%,AVANCE[[#This Row],[CANALIZACIÓN]]) -> 1 | BT6: =+IF(AVANCE[[#This Row],[CABLEADO]]=AD$2,100%,AVANCE[[#This Row],[CABLEADO]]) -> 1 | BU6: =+IF(AVANCE[[#This Row],[ARTEFACTOS]]=AE$2,100%,AVANCE[[#This Row],[ARTEFACTOS]]) -> 1 | BV6: =+IF(AVANCE[[#This Row],[TABLERO]]=AF$2,100%,AVANCE[[#This Row],[TABLERO]]) -> 1 | BW6: =+IF(AVANCE[[#This Row],[CAJA PAU]]=AG$2,100%,AVANCE[[#This Row],[CAJA PAU]]) -> 1 | BX6: =+IF(AVANCE[[#This Row],[INSTALACION VINILICO]]=AJ$2,100%,AVANCE[[#This Row],[INSTALACION VINILICO]]) -> 1 | BY6: =+IF(AVANCE[[#This Row],[OSB CUBIERTA]]=AK$2,100%,AVANCE[[#This Row],[OSB CUBIERTA]]) -> 1 | BZ6: =+IF(AVANCE[[#This Row],[BARANDA BALCON]]=AL$2,100%,AVANCE[[#This Row],[BARANDA BALCON]]) -> 1 | CA6: =+IF(AVANCE[[#This Row],[OSB EXTERIOR]]=AM$2,100%,AVANCE[[#This Row],[OSB EXTERIOR]]) -> 1 | CB6: =+IF(AVANCE[[#This Row],[SMART PANEL]]=AN$2,100%,AVANCE[[#This Row],[SMART PANEL]]) -> 1 | CC6: =+IF(AVANCE[[#This Row],[PINTURA EXTERIOR]]=AO$2,100%,AVANCE[[#This Row],[PINTURA EXTERIOR]]) -> 1 | CD6: =+IF(AVANCE[[#This Row],[ZOCALOS LOGIA]]=AP$2,100%,AVANCE[[#This Row],[ZOCALOS LOGIA]]) -> 1 | CE6: =+IF(AVANCE[[#This Row],[MOLDURAS]]=AQ$2,100%,AVANCE[[#This Row],[MOLDURAS]]) -> 1 | CF6: =+IF(AVANCE[[#This Row],[PILASTREO]]=AR$2,100%,AVANCE[[#This Row],[PILASTREO]]) -> 1 | CG6: =+IF(AVANCE[[#This Row],[CELOSIAS]]=AS$2,100%,AVANCE[[#This Row],[CELOSIAS]]) -> 1 | CH6: =+IF(AVANCE[[#This Row],[VENTANAS]]=AT$2,100%,AVANCE[[#This Row],[VENTANAS]]) -> 1 | CI6: =+IF(AVANCE[[#This Row],[PUERTAS ACCESO - LOGIA - BANO]]=AU$2,100%,AVANCE[[#This Row],[PUERTAS ACCESO - LOGIA - BANO]]) -> 1 | CJ6: =+IF(AVANCE[[#This Row],[CERRADURAS]]=AV$2,100%,AVANCE[[#This Row],[CERRADURAS]]) -> 1 | CK6: =+IF(AVANCE[[#This Row],[REVESTIMIENTO INTERIOR ZONA SECA]]=AW$2,100%,AVANCE[[#This Row],[REVESTIMIENTO INTERIOR ZONA SECA]]) -> 1 | CL6: =+IF(AVANCE[[#This Row],[REVESTIMIENTO INTERIOR ZONAS HUMEDAS]]=AX$2,100%,AVANCE[[#This Row],[REVESTIMIENTO INTERIOR ZONAS HUMEDAS]]) -> 1 | CM6: =+IF(AVANCE[[#This Row],[MEMBRANA CIELO]]=AY$2,100%,AVANCE[[#This Row],[MEMBRANA CIELO]]) -> 1 | CN6: =+IF(AVANCE[[#This Row],[LIMPIEZA FINAL]]=AZ$2,100%,AVANCE[[#This Row],[LIMPIEZA FINAL]]) -> 1 | CO6: =+IF(AVANCE[[#This Row],[PUERTAS DORMITORIO]]=BA$2,100%,AVANCE[[#This Row],[PUERTAS DORMITORIO]]) -> 1 | CP6: =+IF(AVANCE[[#This Row],[REVESTIMIENTO INTERIOR BANO]]=BB$2,100%,AVANCE[[#This Row],[REVESTIMIENTO INTERIOR BANO]]) -> 1 | CQ6: =+IF(AVANCE[[#This Row],[MUEBLE LAVAPLATOS]]=BC$2,100%,AVANCE[[#This Row],[MUEBLE LAVAPLATOS]]) -> 1 | CR6: =+IF(AVANCE[[#This Row],[IMPERMEABILIZACION BANO - COCINA LOGIA]]=BD$2,100%,AVANCE[[#This Row],[IMPERMEABILIZACION BANO - COCINA LOGIA]]) -> 1 | CS6: =+IF(AVANCE[[#This Row],[ESTADO MODULO]]="PENDIENTE",(TODAY()-AVANCE[[#This Row],[FECHA TERMINO PLANIFICADO]]),0) -> 0 | CT6: {=_xlfn.TEXTJOIN(" | ",TRUE,IF(SUMPRODUCT((BG6:CR6<1)*(PARTIDAS!$I$2:$AT$2="OBRA GRUESA"))>0,"OBRA GRUESA: "&_xlfn.TEXTJOIN(", ",TRUE,IF((BG6:CR6<1)*(PARTIDAS!$I$2:$AT$2="OBRA GRUESA"),PARTIDAS!$I$1:$AT$1,"")),""),IF(SUMPRODUCT((BG6:CR6<1)*(PARTIDAS!$I$2:$AT$2="SANITARIOS"))>0,"SANITARIOS: "&_xlfn.TEXTJOIN(", ",TRUE,IF((BG6:CR6<1)*(PARTIDAS!$I$2:$AT$2="SANITARIOS"),PARTIDAS!$I$1:$AT$1,"")),""),IF(SUMPRODUCT((BG6:CR6<1)*(PARTIDAS!$I$2:$AT$2="ELÉCTRICO"))>0,"ELÉCTRICO: "&_xlfn.TEXTJOIN(", ",TRUE,IF((BG6:CR6<1)*(PARTIDAS!$I$2:$AT$2="ELÉCTRICO"),PARTIDAS!$I$1:$AT$1,"")),""),IF(SUMPRODUCT((BG6:CR6<1)*(PARTIDAS!$I$2:$AT$2="TERMINACIONES"))>0,"TERMINACIONES: "&_xlfn.TEXTJOIN(", ",TRUE,IF((BG6:CR6<1)*(PARTIDAS!$I$2:$AT$2="TERMINACIONES"),PARTIDAS!$I$1:$AT$1,"")),""))} | CU6: {=_xlfn.TEXTJOIN(", ",TRUE,IF(SUMPRODUCT((BG6:CR6<1)*(PARTIDAS!$I$2:$AT$2="OBRA GRUESA"))>0,"OBRA GRUESA",""),IF(SUMPRODUCT((BG6:CR6<1)*(PARTIDAS!$I$2:$AT$2="SANITARIOS"))>0,"SANITARIOS",""),IF(SUMPRODUCT((BG6:CR6<1)*(PARTIDAS!$I$2:$AT$2="ELÉCTRICO"))>0,"ELÉCTRICO",""),IF(SUMPRODUCT((BG6:CR6<1)*(PARTIDAS!$I$2:$AT$2="TERMINACIONES"))>0,"TERMINACIONES",""))} | CV6: {=SUMPRODUCT(--(BG6:CR6<1))} -> 0
A7: TORRE 01 | B7: M-00006 | C7: 2302600006 | D7: HUMEDO | E7: 1 | F7: 46105 | G7: 46105 | H7: 46169 | I7: 46153 | K7: 46169 | L7: 0.43 | M7: 1 | N7: 0.27906977 | O7: 0.18604651 | P7: 0.25581395 | Q7: 0.18604651 | R7: 0.093023256 | S7: 0.09 | T7: 1 | U7: 0.22222222 | V7: 0.22222222 | W7: 0.11111111 | X7: 0.11111111 | Y7: 0.11111111 | Z7: 0.22222222 | AA7: 0.11 | AB7: 1 | AC7: 0.27272727 | AD7: 0.27272727 | AE7: 0.090909091 | AF7: 0.18181818 | AG7: 0.18181818 | AH7: 0.37 | AI7: 1 | AJ7: 0.054054054 | AK7: 0.054054054 | AL7: 0.027027027 | AM7: 0.081081081 | AN7: 0.081081081 | AO7: 0.067567568 | AP7: 0.054054054 | AQ7: 0.013513514 | AR7: 0.040540541 | AS7: 0.013513514 | AT7: 0.081081081 | AU7: 0.054054054 | AV7: 0.027027027 | AW7: 0.054054054 | AX7: 0.054054054 | AY7: 0.027027027 | AZ7: 0.040540541 | BA7: 0.054054054 | BB7: 0.081081081 | BC7: 0.013513514 | BD7: 0.027027027 | BE7: 31.32 | BF7: =+IF(AVANCE[[#This Row],[% AVANCE]]=100%,"MODULO TERMINADO",IF(AVANCE[[#This Row],[FECHA INICIO REAL]]="","MODULO NO INICIADO","PENDIENTE")) -> MODULO TERMINADO | BG7: =+IF(AVANCE[[#This Row],[VENTANAS]]=8.10810810810811%,100%,AVANCE[[#This Row],[VENTANAS]]) -> 1 | BH7: =+IF(AVANCE[[#This Row],[PISO]]=N$2,100%,AVANCE[[#This Row],[PISO]]) -> 1 | BI7: =+IF(AVANCE[[#This Row],[TABIQUES]]=O$2,100%,AVANCE[[#This Row],[TABIQUES]]) -> 1 | BJ7: =+IF(AVANCE[[#This Row],[MUROS]]=P$2,100%,AVANCE[[#This Row],[MUROS]]) -> 1 | BK7: =+IF(AVANCE[[#This Row],[CIELO]]=Q$2,100%,AVANCE[[#This Row],[CIELO]]) -> 1 | BL7: =+IF(AVANCE[[#This Row],[BALCÓN]]=R$2,100%,AVANCE[[#This Row],[BALCÓN]]) -> 1 | BM7: =+IF(AVANCE[[#This Row],[RED ALCANTARILLADO]]=U$2,100%,AVANCE[[#This Row],[RED ALCANTARILLADO]]) -> 1 | BN7: =+IF(AVANCE[[#This Row],[RED DE AGUA]]=V$2,100%,AVANCE[[#This Row],[RED DE AGUA]]) -> 1 | BO7: =+IF(AVANCE[[#This Row],[VENTILACIONES]]=W$2,100%,AVANCE[[#This Row],[VENTILACIONES]]) -> 1 | BP7: =+IF(AVANCE[[#This Row],[TINA]]=X$2,100%,AVANCE[[#This Row],[TINA]]) -> 1 | BQ7: =+IF(AVANCE[[#This Row],[WC]]=Y$2,100%,AVANCE[[#This Row],[WC]]) -> 1 | BR7: =+IF(AVANCE[[#This Row],[LAVAMANOS / LAVAPLATOS / LAVADERO]]=Z$2,100%,AVANCE[[#This Row],[LAVAMANOS / LAVAPLATOS / LAVADERO]]) -> 1 | BS7: =+IF(AVANCE[[#This Row],[CANALIZACIÓN]]=AC$2,100%,AVANCE[[#This Row],[CANALIZACIÓN]]) -> 1 | BT7: =+IF(AVANCE[[#This Row],[CABLEADO]]=AD$2,100%,AVANCE[[#This Row],[CABLEADO]]) -> 1 | BU7: =+IF(AVANCE[[#This Row],[ARTEFACTOS]]=AE$2,100%,AVANCE[[#This Row],[ARTEFACTOS]]) -> 1 | BV7: =+IF(AVANCE[[#This Row],[TABLERO]]=AF$2,100%,AVANCE[[#This Row],[TABLERO]]) -> 1 | BW7: =+IF(AVANCE[[#This Row],[CAJA PAU]]=AG$2,100%,AVANCE[[#This Row],[CAJA PAU]]) -> 1 | BX7: =+IF(AVANCE[[#This Row],[INSTALACION VINILICO]]=AJ$2,100%,AVANCE[[#This Row],[INSTALACION VINILICO]]) -> 1 | BY7: =+IF(AVANCE[[#This Row],[OSB CUBIERTA]]=AK$2,100%,AVANCE[[#This Row],[OSB CUBIERTA]]) -> 1 | BZ7: =+IF(AVANCE[[#This Row],[BARANDA BALCON]]=AL$2,100%,AVANCE[[#This Row],[BARANDA BALCON]]) -> 1 | CA7: =+IF(AVANCE[[#This Row],[OSB EXTERIOR]]=AM$2,100%,AVANCE[[#This Row],[OSB EXTERIOR]]) -> 1 | CB7: =+IF(AVANCE[[#This Row],[SMART PANEL]]=AN$2,100%,AVANCE[[#This Row],[SMART PANEL]]) -> 1 | CC7: =+IF(AVANCE[[#This Row],[PINTURA EXTERIOR]]=AO$2,100%,AVANCE[[#This Row],[PINTURA EXTERIOR]]) -> 1 | CD7: =+IF(AVANCE[[#This Row],[ZOCALOS LOGIA]]=AP$2,100%,AVANCE[[#This Row],[ZOCALOS LOGIA]]) -> 1 | CE7: =+IF(AVANCE[[#This Row],[MOLDURAS]]=AQ$2,100%,AVANCE[[#This Row],[MOLDURAS]]) -> 1 | CF7: =+IF(AVANCE[[#This Row],[PILASTREO]]=AR$2,100%,AVANCE[[#This Row],[PILASTREO]]) -> 1 | CG7: =+IF(AVANCE[[#This Row],[CELOSIAS]]=AS$2,100%,AVANCE[[#This Row],[CELOSIAS]]) -> 1 | CH7: =+IF(AVANCE[[#This Row],[VENTANAS]]=AT$2,100%,AVANCE[[#This Row],[VENTANAS]]) -> 1 | CI7: =+IF(AVANCE[[#This Row],[PUERTAS ACCESO - LOGIA - BANO]]=AU$2,100%,AVANCE[[#This Row],[PUERTAS ACCESO - LOGIA - BANO]]) -> 1 | CJ7: =+IF(AVANCE[[#This Row],[CERRADURAS]]=AV$2,100%,AVANCE[[#This Row],[CERRADURAS]]) -> 1 | CK7: =+IF(AVANCE[[#This Row],[REVESTIMIENTO INTERIOR ZONA SECA]]=AW$2,100%,AVANCE[[#This Row],[REVESTIMIENTO INTERIOR ZONA SECA]]) -> 1 | CL7: =+IF(AVANCE[[#This Row],[REVESTIMIENTO INTERIOR ZONAS HUMEDAS]]=AX$2,100%,AVANCE[[#This Row],[REVESTIMIENTO INTERIOR ZONAS HUMEDAS]]) -> 1 | CM7: =+IF(AVANCE[[#This Row],[MEMBRANA CIELO]]=AY$2,100%,AVANCE[[#This Row],[MEMBRANA CIELO]]) -> 1 | CN7: =+IF(AVANCE[[#This Row],[LIMPIEZA FINAL]]=AZ$2,100%,AVANCE[[#This Row],[LIMPIEZA FINAL]]) -> 1 | CO7: =+IF(AVANCE[[#This Row],[PUERTAS DORMITORIO]]=BA$2,100%,AVANCE[[#This Row],[PUERTAS DORMITORIO]]) -> 1 | CP7: =+IF(AVANCE[[#This Row],[REVESTIMIENTO INTERIOR BANO]]=BB$2,100%,AVANCE[[#This Row],[REVESTIMIENTO INTERIOR BANO]]) -> 1 | CQ7: =+IF(AVANCE[[#This Row],[MUEBLE LAVAPLATOS]]=BC$2,100%,AVANCE[[#This Row],[MUEBLE LAVAPLATOS]]) -> 1 | CR7: =+IF(AVANCE[[#This Row],[IMPERMEABILIZACION BANO - COCINA LOGIA]]=BD$2,100%,AVANCE[[#This Row],[IMPERMEABILIZACION BANO - COCINA LOGIA]]) -> 1 | CS7: =+IF(AVANCE[[#This Row],[ESTADO MODULO]]="PENDIENTE",(TODAY()-AVANCE[[#This Row],[FECHA TERMINO PLANIFICADO]]),0) -> 0 | CT7: {=_xlfn.TEXTJOIN(" | ",TRUE,IF(SUMPRODUCT((BG7:CR7<1)*(PARTIDAS!$I$2:$AT$2="OBRA GRUESA"))>0,"OBRA GRUESA: "&_xlfn.TEXTJOIN(", ",TRUE,IF((BG7:CR7<1)*(PARTIDAS!$I$2:$AT$2="OBRA GRUESA"),PARTIDAS!$I$1:$AT$1,"")),""),IF(SUMPRODUCT((BG7:CR7<1)*(PARTIDAS!$I$2:$AT$2="SANITARIOS"))>0,"SANITARIOS: "&_xlfn.TEXTJOIN(", ",TRUE,IF((BG7:CR7<1)*(PARTIDAS!$I$2:$AT$2="SANITARIOS"),PARTIDAS!$I$1:$AT$1,"")),""),IF(SUMPRODUCT((BG7:CR7<1)*(PARTIDAS!$I$2:$AT$2="ELÉCTRICO"))>0,"ELÉCTRICO: "&_xlfn.TEXTJOIN(", ",TRUE,IF((BG7:CR7<1)*(PARTIDAS!$I$2:$AT$2="ELÉCTRICO"),PARTIDAS!$I$1:$AT$1,"")),""),IF(SUMPRODUCT((BG7:CR7<1)*(PARTIDAS!$I$2:$AT$2="TERMINACIONES"))>0,"TERMINACIONES: "&_xlfn.TEXTJOIN(", ",TRUE,IF((BG7:CR7<1)*(PARTIDAS!$I$2:$AT$2="TERMINACIONES"),PARTIDAS!$I$1:$AT$1,"")),""))} | CU7: {=_xlfn.TEXTJOIN(", ",TRUE,IF(SUMPRODUCT((BG7:CR7<1)*(PARTIDAS!$I$2:$AT$2="OBRA GRUESA"))>0,"OBRA GRUESA",""),IF(SUMPRODUCT((BG7:CR7<1)*(PARTIDAS!$I$2:$AT$2="SANITARIOS"))>0,"SANITARIOS",""),IF(SUMPRODUCT((BG7:CR7<1)*(PARTIDAS!$I$2:$AT$2="ELÉCTRICO"))>0,"ELÉCTRICO",""),IF(SUMPRODUCT((BG7:CR7<1)*(PARTIDAS!$I$2:$AT$2="TERMINACIONES"))>0,"TERMINACIONES",""))} | CV7: {=SUMPRODUCT(--(BG7:CR7<1))} -> 0
A8: TORRE 01 | B8: M-00007 | C8: 2302600007 | D8: HUMEDO | E8: 1 | F8: 46105 | G8: 46105 | H8: 46178 | I8: 46155 | K8: 46178 | L8: 0.43 | M8: 1 | N8: 0.27906977 | O8: 0.18604651 | P8: 0.25581395 | Q8: 0.18604651 | R8: 0.093023256 | S8: 0.09 | T8: 1 | U8: 0.22222222 | V8: 0.22222222 | W8: 0.11111111 | X8: 0.11111111 | Y8: 0.11111111 | Z8: 0.22222222 | AA8: 0.11 | AB8: 1 | AC8: 0.27272727 | AD8: 0.27272727 | AE8: 0.090909091 | AF8: 0.18181818 | AG8: 0.18181818 | AH8: 0.37 | AI8: 1 | AJ8: 0.054054054 | AK8: 0.054054054 | AL8: 0.027027027 | AM8: 0.081081081 | AN8: 0.081081081 | AO8: 0.067567568 | AP8: 0.054054054 | AQ8: 0.013513514 | AR8: 0.040540541 | AS8: 0.013513514 | AT8: 0.081081081 | AU8: 0.054054054 | AV8: 0.027027027 | AW8: 0.054054054 | AX8: 0.054054054 | AY8: 0.027027027 | AZ8: 0.040540541 | BA8: 0.054054054 | BB8: 0.081081081 | BC8: 0.013513514 | BD8: 0.027027027 | BE8: 31.32 | BF8: =+IF(AVANCE[[#This Row],[% AVANCE]]=100%,"MODULO TERMINADO",IF(AVANCE[[#This Row],[FECHA INICIO REAL]]="","MODULO NO INICIADO","PENDIENTE")) -> MODULO TERMINADO | BG8: =+IF(AVANCE[[#This Row],[VENTANAS]]=8.10810810810811%,100%,AVANCE[[#This Row],[VENTANAS]]) -> 1 | BH8: =+IF(AVANCE[[#This Row],[PISO]]=N$2,100%,AVANCE[[#This Row],[PISO]]) -> 1 | BI8: =+IF(AVANCE[[#This Row],[TABIQUES]]=O$2,100%,AVANCE[[#This Row],[TABIQUES]]) -> 1 | BJ8: =+IF(AVANCE[[#This Row],[MUROS]]=P$2,100%,AVANCE[[#This Row],[MUROS]]) -> 1 | BK8: =+IF(AVANCE[[#This Row],[CIELO]]=Q$2,100%,AVANCE[[#This Row],[CIELO]]) -> 1 | BL8: =+IF(AVANCE[[#This Row],[BALCÓN]]=R$2,100%,AVANCE[[#This Row],[BALCÓN]]) -> 1 | BM8: =+IF(AVANCE[[#This Row],[RED ALCANTARILLADO]]=U$2,100%,AVANCE[[#This Row],[RED ALCANTARILLADO]]) -> 1 | BN8: =+IF(AVANCE[[#This Row],[RED DE AGUA]]=V$2,100%,AVANCE[[#This Row],[RED DE AGUA]]) -> 1 | BO8: =+IF(AVANCE[[#This Row],[VENTILACIONES]]=W$2,100%,AVANCE[[#This Row],[VENTILACIONES]]) -> 1 | BP8: =+IF(AVANCE[[#This Row],[TINA]]=X$2,100%,AVANCE[[#This Row],[TINA]]) -> 1 | BQ8: =+IF(AVANCE[[#This Row],[WC]]=Y$2,100%,AVANCE[[#This Row],[WC]]) -> 1 | BR8: =+IF(AVANCE[[#This Row],[LAVAMANOS / LAVAPLATOS / LAVADERO]]=Z$2,100%,AVANCE[[#This Row],[LAVAMANOS / LAVAPLATOS / LAVADERO]]) -> 1 | BS8: =+IF(AVANCE[[#This Row],[CANALIZACIÓN]]=AC$2,100%,AVANCE[[#This Row],[CANALIZACIÓN]]) -> 1 | BT8: =+IF(AVANCE[[#This Row],[CABLEADO]]=AD$2,100%,AVANCE[[#This Row],[CABLEADO]]) -> 1 | BU8: =+IF(AVANCE[[#This Row],[ARTEFACTOS]]=AE$2,100%,AVANCE[[#This Row],[ARTEFACTOS]]) -> 1 | BV8: =+IF(AVANCE[[#This Row],[TABLERO]]=AF$2,100%,AVANCE[[#This Row],[TABLERO]]) -> 1 | BW8: =+IF(AVANCE[[#This Row],[CAJA PAU]]=AG$2,100%,AVANCE[[#This Row],[CAJA PAU]]) -> 1 | BX8: =+IF(AVANCE[[#This Row],[INSTALACION VINILICO]]=AJ$2,100%,AVANCE[[#This Row],[INSTALACION VINILICO]]) -> 1 | BY8: =+IF(AVANCE[[#This Row],[OSB CUBIERTA]]=AK$2,100%,AVANCE[[#This Row],[OSB CUBIERTA]]) -> 1 | BZ8: =+IF(AVANCE[[#This Row],[BARANDA BALCON]]=AL$2,100%,AVANCE[[#This Row],[BARANDA BALCON]]) -> 1 | CA8: =+IF(AVANCE[[#This Row],[OSB EXTERIOR]]=AM$2,100%,AVANCE[[#This Row],[OSB EXTERIOR]]) -> 1 | CB8: =+IF(AVANCE[[#This Row],[SMART PANEL]]=AN$2,100%,AVANCE[[#This Row],[SMART PANEL]]) -> 1 | CC8: =+IF(AVANCE[[#This Row],[PINTURA EXTERIOR]]=AO$2,100%,AVANCE[[#This Row],[PINTURA EXTERIOR]]) -> 1 | CD8: =+IF(AVANCE[[#This Row],[ZOCALOS LOGIA]]=AP$2,100%,AVANCE[[#This Row],[ZOCALOS LOGIA]]) -> 1 | CE8: =+IF(AVANCE[[#This Row],[MOLDURAS]]=AQ$2,100%,AVANCE[[#This Row],[MOLDURAS]]) -> 1 | CF8: =+IF(AVANCE[[#This Row],[PILASTREO]]=AR$2,100%,AVANCE[[#This Row],[PILASTREO]]) -> 1 | CG8: =+IF(AVANCE[[#This Row],[CELOSIAS]]=AS$2,100%,AVANCE[[#This Row],[CELOSIAS]]) -> 1 | CH8: =+IF(AVANCE[[#This Row],[VENTANAS]]=AT$2,100%,AVANCE[[#This Row],[VENTANAS]]) -> 1 | CI8: =+IF(AVANCE[[#This Row],[PUERTAS ACCESO - LOGIA - BANO]]=AU$2,100%,AVANCE[[#This Row],[PUERTAS ACCESO - LOGIA - BANO]]) -> 1 | CJ8: =+IF(AVANCE[[#This Row],[CERRADURAS]]=AV$2,100%,AVANCE[[#This Row],[CERRADURAS]]) -> 1 | CK8: =+IF(AVANCE[[#This Row],[REVESTIMIENTO INTERIOR ZONA SECA]]=AW$2,100%,AVANCE[[#This Row],[REVESTIMIENTO INTERIOR ZONA SECA]]) -> 1 | CL8: =+IF(AVANCE[[#This Row],[REVESTIMIENTO INTERIOR ZONAS HUMEDAS]]=AX$2,100%,AVANCE[[#This Row],[REVESTIMIENTO INTERIOR ZONAS HUMEDAS]]) -> 1 | CM8: =+IF(AVANCE[[#This Row],[MEMBRANA CIELO]]=AY$2,100%,AVANCE[[#This Row],[MEMBRANA CIELO]]) -> 1 | CN8: =+IF(AVANCE[[#This Row],[LIMPIEZA FINAL]]=AZ$2,100%,AVANCE[[#This Row],[LIMPIEZA FINAL]]) -> 1 | CO8: =+IF(AVANCE[[#This Row],[PUERTAS DORMITORIO]]=BA$2,100%,AVANCE[[#This Row],[PUERTAS DORMITORIO]]) -> 1 | CP8: =+IF(AVANCE[[#This Row],[REVESTIMIENTO INTERIOR BANO]]=BB$2,100%,AVANCE[[#This Row],[REVESTIMIENTO INTERIOR BANO]]) -> 1 | CQ8: =+IF(AVANCE[[#This Row],[MUEBLE LAVAPLATOS]]=BC$2,100%,AVANCE[[#This Row],[MUEBLE LAVAPLATOS]]) -> 1 | CR8: =+IF(AVANCE[[#This Row],[IMPERMEABILIZACION BANO - COCINA LOGIA]]=BD$2,100%,AVANCE[[#This Row],[IMPERMEABILIZACION BANO - COCINA LOGIA]]) -> 1 | CS8: =+IF(AVANCE[[#This Row],[ESTADO MODULO]]="PENDIENTE",(TODAY()-AVANCE[[#This Row],[FECHA TERMINO PLANIFICADO]]),0) -> 0 | CT8: {=_xlfn.TEXTJOIN(" | ",TRUE,IF(SUMPRODUCT((BG8:CR8<1)*(PARTIDAS!$I$2:$AT$2="OBRA GRUESA"))>0,"OBRA GRUESA: "&_xlfn.TEXTJOIN(", ",TRUE,IF((BG8:CR8<1)*(PARTIDAS!$I$2:$AT$2="OBRA GRUESA"),PARTIDAS!$I$1:$AT$1,"")),""),IF(SUMPRODUCT((BG8:CR8<1)*(PARTIDAS!$I$2:$AT$2="SANITARIOS"))>0,"SANITARIOS: "&_xlfn.TEXTJOIN(", ",TRUE,IF((BG8:CR8<1)*(PARTIDAS!$I$2:$AT$2="SANITARIOS"),PARTIDAS!$I$1:$AT$1,"")),""),IF(SUMPRODUCT((BG8:CR8<1)*(PARTIDAS!$I$2:$AT$2="ELÉCTRICO"))>0,"ELÉCTRICO: "&_xlfn.TEXTJOIN(", ",TRUE,IF((BG8:CR8<1)*(PARTIDAS!$I$2:$AT$2="ELÉCTRICO"),PARTIDAS!$I$1:$AT$1,"")),""),IF(SUMPRODUCT((BG8:CR8<1)*(PARTIDAS!$I$2:$AT$2="TERMINACIONES"))>0,"TERMINACIONES: "&_xlfn.TEXTJOIN(", ",TRUE,IF((BG8:CR8<1)*(PARTIDAS!$I$2:$AT$2="TERMINACIONES"),PARTIDAS!$I$1:$AT$1,"")),""))} | CU8: {=_xlfn.TEXTJOIN(", ",TRUE,IF(SUMPRODUCT((BG8:CR8<1)*(PARTIDAS!$I$2:$AT$2="OBRA GRUESA"))>0,"OBRA GRUESA",""),IF(SUMPRODUCT((BG8:CR8<1)*(PARTIDAS!$I$2:$AT$2="SANITARIOS"))>0,"SANITARIOS",""),IF(SUMPRODUCT((BG8:CR8<1)*(PARTIDAS!$I$2:$AT$2="ELÉCTRICO"))>0,"ELÉCTRICO",""),IF(SUMPRODUCT((BG8:CR8<1)*(PARTIDAS!$I$2:$AT$2="TERMINACIONES"))>0,"TERMINACIONES",""))} | CV8: {=SUMPRODUCT(--(BG8:CR8<1))} -> 0
A9: TORRE 01 | B9: M-00008 | C9: 2282600008 | D9: SECO | E9: 1 | F9: 46106 | G9: 46106 | H9: 46177 | I9: 46148 | K9: 46177 | L9: 0.43 | M9: 1 | N9: 0.27906977 | O9: 0.18604651 | P9: 0.25581395 | Q9: 0.18604651 | R9: 0.093023256 | S9: 0.09 | T9: 1 | U9: 0.22222222 | V9: 0.22222222 | W9: 0.11111111 | X9: 0.11111111 | Y9: 0.11111111 | Z9: 0.22222222 | AA9: 0.11 | AB9: 1 | AC9: 0.27272727 | AD9: 0.27272727 | AE9: 0.090909091 | AF9: 0.18181818 | AG9: 0.18181818 | AH9: 0.37 | AI9: 1 | AJ9: 0.054054054 | AK9: 0.054054054 | AL9: 0.027027027 | AM9: 0.081081081 | AN9: 0.081081081 | AO9: 0.067567568 | AP9: 0.054054054 | AQ9: 0.013513514 | AR9: 0.040540541 | AS9: 0.013513514 | AT9: 0.081081081 | AU9: 0.054054054 | AV9: 0.027027027 | AW9: 0.054054054 | AX9: 0.054054054 | AY9: 0.027027027 | AZ9: 0.040540541 | BA9: 0.054054054 | BB9: 0.081081081 | BC9: 0.013513514 | BD9: 0.027027027 | BE9: 28.87 | BF9: =+IF(AVANCE[[#This Row],[% AVANCE]]=100%,"MODULO TERMINADO",IF(AVANCE[[#This Row],[FECHA INICIO REAL]]="","MODULO NO INICIADO","PENDIENTE")) -> MODULO TERMINADO | BG9: =+IF(AVANCE[[#This Row],[VENTANAS]]=8.10810810810811%,100%,AVANCE[[#This Row],[VENTANAS]]) -> 1 | BH9: =+IF(AVANCE[[#This Row],[PISO]]=N$2,100%,AVANCE[[#This Row],[PISO]]) -> 1 | BI9: =+IF(AVANCE[[#This Row],[TABIQUES]]=O$2,100%,AVANCE[[#This Row],[TABIQUES]]) -> 1 | BJ9: =+IF(AVANCE[[#This Row],[MUROS]]=P$2,100%,AVANCE[[#This Row],[MUROS]]) -> 1 | BK9: =+IF(AVANCE[[#This Row],[CIELO]]=Q$2,100%,AVANCE[[#This Row],[CIELO]]) -> 1 | BL9: =+IF(AVANCE[[#This Row],[BALCÓN]]=R$2,100%,AVANCE[[#This Row],[BALCÓN]]) -> 1 | BM9: =+IF(AVANCE[[#This Row],[RED ALCANTARILLADO]]=U$2,100%,AVANCE[[#This Row],[RED ALCANTARILLADO]]) -> 1 | BN9: =+IF(AVANCE[[#This Row],[RED DE AGUA]]=V$2,100%,AVANCE[[#This Row],[RED DE AGUA]]) -> 1 | BO9: =+IF(AVANCE[[#This Row],[VENTILACIONES]]=W$2,100%,AVANCE[[#This Row],[VENTILACIONES]]) -> 1 | BP9: =+IF(AVANCE[[#This Row],[TINA]]=X$2,100%,AVANCE[[#This Row],[TINA]]) -> 1 | BQ9: =+IF(AVANCE[[#This Row],[WC]]=Y$2,100%,AVANCE[[#This Row],[WC]]) -> 1 | BR9: =+IF(AVANCE[[#This Row],[LAVAMANOS / LAVAPLATOS / LAVADERO]]=Z$2,100%,AVANCE[[#This Row],[LAVAMANOS / LAVAPLATOS / LAVADERO]]) -> 1 | BS9: =+IF(AVANCE[[#This Row],[CANALIZACIÓN]]=AC$2,100%,AVANCE[[#This Row],[CANALIZACIÓN]]) -> 1 | BT9: =+IF(AVANCE[[#This Row],[CABLEADO]]=AD$2,100%,AVANCE[[#This Row],[CABLEADO]]) -> 1 | BU9: =+IF(AVANCE[[#This Row],[ARTEFACTOS]]=AE$2,100%,AVANCE[[#This Row],[ARTEFACTOS]]) -> 1 | BV9: =+IF(AVANCE[[#This Row],[TABLERO]]=AF$2,100%,AVANCE[[#This Row],[TABLERO]]) -> 1 | BW9: =+IF(AVANCE[[#This Row],[CAJA PAU]]=AG$2,100%,AVANCE[[#This Row],[CAJA PAU]]) -> 1 | BX9: =+IF(AVANCE[[#This Row],[INSTALACION VINILICO]]=AJ$2,100%,AVANCE[[#This Row],[INSTALACION VINILICO]]) -> 1 | BY9: =+IF(AVANCE[[#This Row],[OSB CUBIERTA]]=AK$2,100%,AVANCE[[#This Row],[OSB CUBIERTA]]) -> 1 | BZ9: =+IF(AVANCE[[#This Row],[BARANDA BALCON]]=AL$2,100%,AVANCE[[#This Row],[BARANDA BALCON]]) -> 1 | CA9: =+IF(AVANCE[[#This Row],[OSB EXTERIOR]]=AM$2,100%,AVANCE[[#This Row],[OSB EXTERIOR]]) -> 1 | CB9: =+IF(AVANCE[[#This Row],[SMART PANEL]]=AN$2,100%,AVANCE[[#This Row],[SMART PANEL]]) -> 1 | CC9: =+IF(AVANCE[[#This Row],[PINTURA EXTERIOR]]=AO$2,100%,AVANCE[[#This Row],[PINTURA EXTERIOR]]) -> 1 | CD9: =+IF(AVANCE[[#This Row],[ZOCALOS LOGIA]]=AP$2,100%,AVANCE[[#This Row],[ZOCALOS LOGIA]]) -> 1 | CE9: =+IF(AVANCE[[#This Row],[MOLDURAS]]=AQ$2,100%,AVANCE[[#This Row],[MOLDURAS]]) -> 1 | CF9: =+IF(AVANCE[[#This Row],[PILASTREO]]=AR$2,100%,AVANCE[[#This Row],[PILASTREO]]) -> 1 | CG9: =+IF(AVANCE[[#This Row],[CELOSIAS]]=AS$2,100%,AVANCE[[#This Row],[CELOSIAS]]) -> 1 | CH9: =+IF(AVANCE[[#This Row],[VENTANAS]]=AT$2,100%,AVANCE[[#This Row],[VENTANAS]]) -> 1 | CI9: =+IF(AVANCE[[#This Row],[PUERTAS ACCESO - LOGIA - BANO]]=AU$2,100%,AVANCE[[#This Row],[PUERTAS ACCESO - LOGIA - BANO]]) -> 1 | CJ9: =+IF(AVANCE[[#This Row],[CERRADURAS]]=AV$2,100%,AVANCE[[#This Row],[CERRADURAS]]) -> 1 | CK9: =+IF(AVANCE[[#This Row],[REVESTIMIENTO INTERIOR ZONA SECA]]=AW$2,100%,AVANCE[[#This Row],[REVESTIMIENTO INTERIOR ZONA SECA]]) -> 1 | CL9: =+IF(AVANCE[[#This Row],[REVESTIMIENTO INTERIOR ZONAS HUMEDAS]]=AX$2,100%,AVANCE[[#This Row],[REVESTIMIENTO INTERIOR ZONAS HUMEDAS]]) -> 1 | CM9: =+IF(AVANCE[[#This Row],[MEMBRANA CIELO]]=AY$2,100%,AVANCE[[#This Row],[MEMBRANA CIELO]]) -> 1 | CN9: =+IF(AVANCE[[#This Row],[LIMPIEZA FINAL]]=AZ$2,100%,AVANCE[[#This Row],[LIMPIEZA FINAL]]) -> 1 | CO9: =+IF(AVANCE[[#This Row],[PUERTAS DORMITORIO]]=BA$2,100%,AVANCE[[#This Row],[PUERTAS DORMITORIO]]) -> 1 | CP9: =+IF(AVANCE[[#This Row],[REVESTIMIENTO INTERIOR BANO]]=BB$2,100%,AVANCE[[#This Row],[REVESTIMIENTO INTERIOR BANO]]) -> 1 | CQ9: =+IF(AVANCE[[#This Row],[MUEBLE LAVAPLATOS]]=BC$2,100%,AVANCE[[#This Row],[MUEBLE LAVAPLATOS]]) -> 1 | CR9: =+IF(AVANCE[[#This Row],[IMPERMEABILIZACION BANO - COCINA LOGIA]]=BD$2,100%,AVANCE[[#This Row],[IMPERMEABILIZACION BANO - COCINA LOGIA]]) -> 1 | CS9: =+IF(AVANCE[[#This Row],[ESTADO MODULO]]="PENDIENTE",(TODAY()-AVANCE[[#This Row],[FECHA TERMINO PLANIFICADO]]),0) -> 0 | CT9: {=_xlfn.TEXTJOIN(" | ",TRUE,IF(SUMPRODUCT((BG9:CR9<1)*(PARTIDAS!$I$2:$AT$2="OBRA GRUESA"))>0,"OBRA GRUESA: "&_xlfn.TEXTJOIN(", ",TRUE,IF((BG9:CR9<1)*(PARTIDAS!$I$2:$AT$2="OBRA GRUESA"),PARTIDAS!$I$1:$AT$1,"")),""),IF(SUMPRODUCT((BG9:CR9<1)*(PARTIDAS!$I$2:$AT$2="SANITARIOS"))>0,"SANITARIOS: "&_xlfn.TEXTJOIN(", ",TRUE,IF((BG9:CR9<1)*(PARTIDAS!$I$2:$AT$2="SANITARIOS"),PARTIDAS!$I$1:$AT$1,"")),""),IF(SUMPRODUCT((BG9:CR9<1)*(PARTIDAS!$I$2:$AT$2="ELÉCTRICO"))>0,"ELÉCTRICO: "&_xlfn.TEXTJOIN(", ",TRUE,IF((BG9:CR9<1)*(PARTIDAS!$I$2:$AT$2="ELÉCTRICO"),PARTIDAS!$I$1:$AT$1,"")),""),IF(SUMPRODUCT((BG9:CR9<1)*(PARTIDAS!$I$2:$AT$2="TERMINACIONES"))>0,"TERMINACIONES: "&_xlfn.TEXTJOIN(", ",TRUE,IF((BG9:CR9<1)*(PARTIDAS!$I$2:$AT$2="TERMINACIONES"),PARTIDAS!$I$1:$AT$1,"")),""))} | CU9: {=_xlfn.TEXTJOIN(", ",TRUE,IF(SUMPRODUCT((BG9:CR9<1)*(PARTIDAS!$I$2:$AT$2="OBRA GRUESA"))>0,"OBRA GRUESA",""),IF(SUMPRODUCT((BG9:CR9<1)*(PARTIDAS!$I$2:$AT$2="SANITARIOS"))>0,"SANITARIOS",""),IF(SUMPRODUCT((BG9:CR9<1)*(PARTIDAS!$I$2:$AT$2="ELÉCTRICO"))>0,"ELÉCTRICO",""),IF(SUMPRODUCT((BG9:CR9<1)*(PARTIDAS!$I$2:$AT$2="TERMINACIONES"))>0,"TERMINACIONES",""))} | CV9: {=SUMPRODUCT(--(BG9:CR9<1))} -> 0
A10: TORRE 01 | B10: M-00009 | C10: 2282600009 | D10: SECO | E10: 1 | F10: 46070 | G10: 46070 | H10: 46156 | I10: 46134 | K10: 46156 | L10: 0.43 | M10: 1 | N10: 0.27906977 | O10: 0.18604651 | P10: 0.25581395 | Q10: 0.18604651 | R10: 0.093023256 | S10: 0.09 | T10: 1 | U10: 0.22222222 | V10: 0.22222222 | W10: 0.11111111 | X10: 0.11111111 | Y10: 0.11111111 | Z10: 0.22222222 | AA10: 0.11 | AB10: 1 | AC10: 0.27272727 | AD10: 0.27272727 | AE10: 0.090909091 | AF10: 0.18181818 | AG10: 0.18181818 | AH10: 0.37 | AI10: 1 | AJ10: 0.054054054 | AK10: 0.054054054 | AL10: 0.027027027 | AM10: 0.081081081 | AN10: 0.081081081 | AO10: 0.067567568 | AP10: 0.054054054 | AQ10: 0.013513514 | AR10: 0.040540541 | AS10: 0.013513514 | AT10: 0.081081081 | AU10: 0.054054054 | AV10: 0.027027027 | AW10: 0.054054054 | AX10: 0.054054054 | AY10: 0.027027027 | AZ10: 0.040540541 | BA10: 0.054054054 | BB10: 0.081081081 | BC10: 0.013513514 | BD10: 0.027027027 | BE10: 28.87 | BF10: =+IF(AVANCE[[#This Row],[% AVANCE]]=100%,"MODULO TERMINADO",IF(AVANCE[[#This Row],[FECHA INICIO REAL]]="","MODULO NO INICIADO","PENDIENTE")) -> MODULO TERMINADO | BG10: =+IF(AVANCE[[#This Row],[VENTANAS]]=8.10810810810811%,100%,AVANCE[[#This Row],[VENTANAS]]) -> 1 | BH10: =+IF(AVANCE[[#This Row],[PISO]]=N$2,100%,AVANCE[[#This Row],[PISO]]) -> 1 | BI10: =+IF(AVANCE[[#This Row],[TABIQUES]]=O$2,100%,AVANCE[[#This Row],[TABIQUES]]) -> 1 | BJ10: =+IF(AVANCE[[#This Row],[MUROS]]=P$2,100%,AVANCE[[#This Row],[MUROS]]) -> 1 | BK10: =+IF(AVANCE[[#This Row],[CIELO]]=Q$2,100%,AVANCE[[#This Row],[CIELO]]) -> 1 | BL10: =+IF(AVANCE[[#This Row],[BALCÓN]]=R$2,100%,AVANCE[[#This Row],[BALCÓN]]) -> 1 | BM10: =+IF(AVANCE[[#This Row],[RED ALCANTARILLADO]]=U$2,100%,AVANCE[[#This Row],[RED ALCANTARILLADO]]) -> 1 | BN10: =+IF(AVANCE[[#This Row],[RED DE AGUA]]=V$2,100%,AVANCE[[#This Row],[RED DE AGUA]]) -> 1 | BO10: =+IF(AVANCE[[#This Row],[VENTILACIONES]]=W$2,100%,AVANCE[[#This Row],[VENTILACIONES]]) -> 1 | BP10: =+IF(AVANCE[[#This Row],[TINA]]=X$2,100%,AVANCE[[#This Row],[TINA]]) -> 1 | BQ10: =+IF(AVANCE[[#This Row],[WC]]=Y$2,100%,AVANCE[[#This Row],[WC]]) -> 1 | BR10: =+IF(AVANCE[[#This Row],[LAVAMANOS / LAVAPLATOS / LAVADERO]]=Z$2,100%,AVANCE[[#This Row],[LAVAMANOS / LAVAPLATOS / LAVADERO]]) -> 1 | BS10: =+IF(AVANCE[[#This Row],[CANALIZACIÓN]]=AC$2,100%,AVANCE[[#This Row],[CANALIZACIÓN]]) -> 1 | BT10: =+IF(AVANCE[[#This Row],[CABLEADO]]=AD$2,100%,AVANCE[[#This Row],[CABLEADO]]) -> 1 | BU10: =+IF(AVANCE[[#This Row],[ARTEFACTOS]]=AE$2,100%,AVANCE[[#This Row],[ARTEFACTOS]]) -> 1 | BV10: =+IF(AVANCE[[#This Row],[TABLERO]]=AF$2,100%,AVANCE[[#This Row],[TABLERO]]) -> 1 | BW10: =+IF(AVANCE[[#This Row],[CAJA PAU]]=AG$2,100%,AVANCE[[#This Row],[CAJA PAU]]) -> 1 | BX10: =+IF(AVANCE[[#This Row],[INSTALACION VINILICO]]=AJ$2,100%,AVANCE[[#This Row],[INSTALACION VINILICO]]) -> 1 | BY10: =+IF(AVANCE[[#This Row],[OSB CUBIERTA]]=AK$2,100%,AVANCE[[#This Row],[OSB CUBIERTA]]) -> 1 | BZ10: =+IF(AVANCE[[#This Row],[BARANDA BALCON]]=AL$2,100%,AVANCE[[#This Row],[BARANDA BALCON]]) -> 1 | CA10: =+IF(AVANCE[[#This Row],[OSB EXTERIOR]]=AM$2,100%,AVANCE[[#This Row],[OSB EXTERIOR]]) -> 1 | CB10: =+IF(AVANCE[[#This Row],[SMART PANEL]]=AN$2,100%,AVANCE[[#This Row],[SMART PANEL]]) -> 1 | CC10: =+IF(AVANCE[[#This Row],[PINTURA EXTERIOR]]=AO$2,100%,AVANCE[[#This Row],[PINTURA EXTERIOR]]) -> 1 | CD10: =+IF(AVANCE[[#This Row],[ZOCALOS LOGIA]]=AP$2,100%,AVANCE[[#This Row],[ZOCALOS LOGIA]]) -> 1 | CE10: =+IF(AVANCE[[#This Row],[MOLDURAS]]=AQ$2,100%,AVANCE[[#This Row],[MOLDURAS]]) -> 1 | CF10: =+IF(AVANCE[[#This Row],[PILASTREO]]=AR$2,100%,AVANCE[[#This Row],[PILASTREO]]) -> 1 | CG10: =+IF(AVANCE[[#This Row],[CELOSIAS]]=AS$2,100%,AVANCE[[#This Row],[CELOSIAS]]) -> 1 | CH10: =+IF(AVANCE[[#This Row],[VENTANAS]]=AT$2,100%,AVANCE[[#This Row],[VENTANAS]]) -> 1 | CI10: =+IF(AVANCE[[#This Row],[PUERTAS ACCESO - LOGIA - BANO]]=AU$2,100%,AVANCE[[#This Row],[PUERTAS ACCESO - LOGIA - BANO]]) -> 1 | CJ10: =+IF(AVANCE[[#This Row],[CERRADURAS]]=AV$2,100%,AVANCE[[#This Row],[CERRADURAS]]) -> 1 | CK10: =+IF(AVANCE[[#This Row],[REVESTIMIENTO INTERIOR ZONA SECA]]=AW$2,100%,AVANCE[[#This Row],[REVESTIMIENTO INTERIOR ZONA SECA]]) -> 1 | CL10: =+IF(AVANCE[[#This Row],[REVESTIMIENTO INTERIOR ZONAS HUMEDAS]]=AX$2,100%,AVANCE[[#This Row],[REVESTIMIENTO INTERIOR ZONAS HUMEDAS]]) -> 1 | CM10: =+IF(AVANCE[[#This Row],[MEMBRANA CIELO]]=AY$2,100%,AVANCE[[#This Row],[MEMBRANA CIELO]]) -> 1 | CN10: =+IF(AVANCE[[#This Row],[LIMPIEZA FINAL]]=AZ$2,100%,AVANCE[[#This Row],[LIMPIEZA FINAL]]) -> 1 | CO10: =+IF(AVANCE[[#This Row],[PUERTAS DORMITORIO]]=BA$2,100%,AVANCE[[#This Row],[PUERTAS DORMITORIO]]) -> 1 | CP10: =+IF(AVANCE[[#This Row],[REVESTIMIENTO INTERIOR BANO]]=BB$2,100%,AVANCE[[#This Row],[REVESTIMIENTO INTERIOR BANO]]) -> 1 | CQ10: =+IF(AVANCE[[#This Row],[MUEBLE LAVAPLATOS]]=BC$2,100%,AVANCE[[#This Row],[MUEBLE LAVAPLATOS]]) -> 1 | CR10: =+IF(AVANCE[[#This Row],[IMPERMEABILIZACION BANO - COCINA LOGIA]]=BD$2,100%,AVANCE[[#This Row],[IMPERMEABILIZACION BANO - COCINA LOGIA]]) -> 1 | CS10: =+IF(AVANCE[[#This Row],[ESTADO MODULO]]="PENDIENTE",(TODAY()-AVANCE[[#This Row],[FECHA TERMINO PLANIFICADO]]),0) -> 0 | CT10: {=_xlfn.TEXTJOIN(" | ",TRUE,IF(SUMPRODUCT((BG10:CR10<1)*(PARTIDAS!$I$2:$AT$2="OBRA GRUESA"))>0,"OBRA GRUESA: "&_xlfn.TEXTJOIN(", ",TRUE,IF((BG10:CR10<1)*(PARTIDAS!$I$2:$AT$2="OBRA GRUESA"),PARTIDAS!$I$1:$AT$1,"")),""),IF(SUMPRODUCT((BG10:CR10<1)*(PARTIDAS!$I$2:$AT$2="SANITARIOS"))>0,"SANITARIOS: "&_xlfn.TEXTJOIN(", ",TRUE,IF((BG10:CR10<1)*(PARTIDAS!$I$2:$AT$2="SANITARIOS"),PARTIDAS!$I$1:$AT$1,"")),""),IF(SUMPRODUCT((BG10:CR10<1)*(PARTIDAS!$I$2:$AT$2="ELÉCTRICO"))>0,"ELÉCTRICO: "&_xlfn.TEXTJOIN(", ",TRUE,IF((BG10:CR10<1)*(PARTIDAS!$I$2:$AT$2="ELÉCTRICO"),PARTIDAS!$I$1:$AT$1,"")),""),IF(SUMPRODUCT((BG10:CR10<1)*(PARTIDAS!$I$2:$AT$2="TERMINACIONES"))>0,"TERMINACIONES: "&_xlfn.TEXTJOIN(", ",TRUE,IF((BG10:CR10<1)*(PARTIDAS!$I$2:$AT$2="TERMINACIONES"),PARTIDAS!$I$1:$AT$1,"")),""))} | CU10: {=_xlfn.TEXTJOIN(", ",TRUE,IF(SUMPRODUCT((BG10:CR10<1)*(PARTIDAS!$I$2:$AT$2="OBRA GRUESA"))>0,"OBRA GRUESA",""),IF(SUMPRODUCT((BG10:CR10<1)*(PARTIDAS!$I$2:$AT$2="SANITARIOS"))>0,"SANITARIOS",""),IF(SUMPRODUCT((BG10:CR10<1)*(PARTIDAS!$I$2:$AT$2="ELÉCTRICO"))>0,"ELÉCTRICO",""),IF(SUMPRODUCT((BG10:CR10<1)*(PARTIDAS!$I$2:$AT$2="TERMINACIONES"))>0,"TERMINACIONES",""))} | CV10: {=SUMPRODUCT(--(BG10:CR10<1))} -> 0
